Workbook
Name david: Equipment!$N$19:$P$21
Name david: 'Screen Inventory'!$P$19:$R$21
Name Header: [1]IFE!$B$3:$AK$3
Name Header: #REF!
Name Header: #REF!
Name Header: [1]IFE!$B$3:$AK$3
Name mine: Equipment!$M$18:$O$18
Name mine: 'Screen Inventory'!$O$18:$Q$18

Sheet Menu
A1: ONE-TRAX Report Menu
A2: * Click Run First Before Viewing, Printing or Saving Reports
A37: Author | B37: IFE Team
A38: Modified By | B38: D. Wilson / D. Ekas
A39: Date Modified | B39: 17 February, 2005
A40: Special Notes | B40: The "Run First" button must be clicked to sort the equipment information for the reports in this template. This template contains mud reporting, mud inventory, equipment, and screen inventory templates.
B41: The Save Final Report macro saves the worksheets as values and removes the links.
B42: The Mud Volume Info sheet was added by Ronnie Primeaux.
B43: The Solids Equipment & Screen costs were added to the mud checks by David Ekas.

Sheet WBM Check
J2: WATER-BASED MUD REPORT No. 16
A3: Operator : | B3: Cardon IV | D3: Field/Area : | E3: Golfo de Venezuela | H3: Depth/TVD : | I3: 2888 ft / | J3: 2888 ft
A4: Report For : | B4: KYLE MORRIS/ JOHNY QUINTERO | D4: Description : | E4: Exploratory | H4: Date : | I4: 39996
A5: Well Name : | B5: Perla-1X | D5: Location : | E5: Offshore | H5: Spud Date : | I5: 39981
A6: Contractor: | B6: Ensco | D6: Water Depth : | E6: 202 ft | H6: Mud Type : | I6: FLUIDO HI VIS
A7: Report For : | B7: WADE HARPER | D7: Rig Name : | E7: 68 | H7: Activity : | I7: POOH-W/CASING
A8: DRILLING ASSEMBLY | C8: CASING | E8: MUD VOLUME (bbl) | G8: CIRCULATION DATA
A9: 1849 ft, 20.-in DP | C9: 30.-in @563 ft (563 TVD) | E9: Hole | F9: Active Pits | H9: Pump Make | I9: NATIONAL 12P-160 | J9: NATIONAL 12P-160
A10: ft, -in | C10: 0 | E10: 1867 | F10: 681 | H10: Pump Liner x Stk | I10: 6,5x12 in | J10: 6,5x12 in
A11: ft, -in | C11: 0 | E11: Total Circulating Volume | H11: Pump Capacity gal/stk | I11: 5.016 | J11: 5.016
A12: ft, -in | C12: 0 | E12: 1866 | H12: Pump stk/min | I12: 65@97% | J12: 65@97%
A13: ft, -in | C13: 0 | E13: Depth Drilled Last 24 hr | H13: Flow Rate | I13: 652 | J13: gal/min
A14: ft, -in | C14: 0 | E14: 0 | F14: ft | H14: Pump Pressure | I14: 650 | J14: psi
A15: Nozzles 0 1/32" | C15: 0 | E15: Volume Drilled Last 24 hr | H15: Bottoms Up | I15: 35.7 min 4646 stk
A16: Bit 26-in 0 | C16: 0 | E16: 0 | F16: bbl | H16: Total Circulation | I16: 120.2 min 15624 stk
A17: MUD PROPERTIES | G17: PRODUCTS USED Last 24 hr
A18: Sample From | C18: TK 2 20:00 | D18: TK 2 1200. | G18: Products | I18: Size | J18: Amount
A19: FlowLine Temp | B19: °F | C19: 0 | D19: 0 | G19: POLYPAC R | I19: 50. LB BG | J19: 17
A20: Depth/TVD | B20: ft | C20: 2880/2880 | D20: 2880/2880 | G20: ENGINEERING SERVICE | I20: 1. EA | J20: 2
A21: Mud Weight /Temp | B21: lb/gal | C21: 10@85 | D21: 10@85 | G21: CAUSTIC SODA | I21: 25. KG BG | J21: 7
A22: Funnel Viscosity | B22: s/qt | C22: 40 | D22: 38 | G22: DUO-VIS | I22: 25. KG BG | J22: 8
A23: Rheology Temp | B23: °F | C23: 120 | D23: 120 | G23: 0 | I23: 0 | J23: 0
A24: R600/R300 | C24: 34/24 | D24: 34/24 | G24: 0 | I24: 0 | J24: 0
A25: R200/R100 | C25: 20/16 | D25: 21/15 | G25: 0 | I25: 0 | J25: 0
A26: R6/R3 | C26: 6/5 | D26: 6/5 | G26: 0 | I26: 0 | J26: 0
A27: PV | B27: cP | C27: 10 | D27: 10 | G27: 0 | I27: 0 | J27: 0
A28: YP | B28: lb/100ft² | C28: 14 | D28: 14 | G28: 0 | I28: 0 | J28: 0
A29: 10s/10m/30m Gel | B29: lb/100ft² | C29: 5/12/16 | D29: 5/12/14 | G29: 0 | I29: 0 | J29: 0
A30: API Fluid Loss | B30: cc/30min | C30: 18 | D30: 18 | G30: 0 | I30: 0 | J30: 0
A31: HTHP Fluid Loss | B31: cc/30min | C31: 0@ | D31: 0@ | G31: 0 | I31: 0 | J31: 0
A32: Cake APT/HT | B32: 1/32" | C32: 1/ | D32: 1/ | G32: 0 | I32: 0 | J32: 0
A33: Solids | B33: %Vol | C33: 8 | D33: 8 | G33: 0 | I33: 0 | J33: 0
A34: Oil/Water | B34: %Vol | C34: /92 | D34: /92 | G34: SOLIDS CONTROL EQUIPMENT Last 24 hr
A35: Sand | B35: %Vol | C35: 0.25 | D35: 0.25 | G35: Type | I35: Model/Size | J35: Hrs Used
A36: MBT | B36: lb/bbl | C36: 15 | D36: 15 | G36: DERRICK SHEKER 1 | I36: 4 X 170 | J36: 7
A37: pH / Temp | C37: 9@85 | D37: 9@85 | G37: DERRICK SHAKER 2 | I37: 2X140 2X100 | J37: 7
A38: Alkal Mud (Pm) | C38: 0.8 | D38: 0.8 | G38: DERRICK SHAKER 3 | I38: 4X170 | J38: 24
A39: Pf/Mf | B39: 0 | C39: 00/00 | D39: 00/00 | G39: MOD 312 / 10T2 w/o pump | I39: 4 X 200 | J39: 24
A40: Chlorides | B40: mg/L | C40: 18000 | D40: 18000 | G40: 0 | I40: 0 | J40: 0
A41: Hardness (Ca++) | C41: 100 | D41: 100 | G41: 0 | I41: 0 | J41: 0
...

Sheet CALDRIL Check
J2: ="CALDRIL MUD REPORT No. "&[1]IFE!B166&" " -> CALDRIL MUD REPORT No. 9
A3: Operator : | B3: =[1]IFE!B6 -> Cardon IV | D3: Field/Area : | E3: =[1]IFE!B9 -> Golfo de Venezuela | H3: Depth/TVD : | I3: =[1]IFE!B120&" "&[1]IFE!B30&" /" -> 563 pies / | J3: =[1]IFE!B121&" "&[1]IFE!B30 -> 563 pies
A4: Report For : | B4: =[1]IFE!B125 -> Gerrit Ham / Jhony Quintero | D4: Description : | E4: =[1]IFE!B10 -> Exploratory | H4: Date : | I4: =[1]IFE!B119 -> 39989
A5: Well Name : | B5: =[1]IFE!B8 -> Perla-1X | D5: Location : | E5: =[1]IFE!B11 -> Offshore | H5: Spud Date : | I5: =[1]IFE!B5 -> 39981
A6: Contractor: | B6: =[1]IFE!B15 -> Ensco | D6: Water Depth : | E6: =[1]IFE!B16&" "&[1]IFE!B30 -> 202 pies | H6: Mud Type : | I6: =[1]IFE!B124 -> Agua de mar / HI VIS
A7: Report For : | B7: =[1]IFE!B126 -> Ricky Otwell | D7: Rig Name : | E7: =[1]IFE!Z981 -> 68 | H7: Activity : | I7: =[1]IFE!B123 -> Bajando Tuberia
A8: DRILLING ASSEMBLY | C8: CASING | E8: ="MUD VOLUME" & " ("& [1]IFE!B32&")" -> MUD VOLUME (bbl) | G8: CIRCULATION DATA
A9: =[1]IFE!B167 -> pies, 5.5-plg DP | C9: =[1]IFE!B173 -> 30.-plg @563 pies (563 TVD) | E9: Hole | F9: Active Pits | H9: Pump Make | I9: =[1]IFE!B161 -> NATIONAL 12P-160 | J9: =[1]IFE!B162 -> NATIONAL 12P-160
A10: =[1]IFE!B168 -> 372 pies, 5.5-plg HWDP | C10: =[1]IFE!B174 -> 0 | E10: =[1]IFE!B177 -> 429 | F10: =[1]IFE!B178 -> 0 | H10: Pump Liner x Stk | I10: =[1]IFE!C161&"x"&[1]IFE!D161&" "&[1]IFE!B31 -> 6,5x12 plg | J10: =[1]IFE!C162&"x"&[1]IFE!D162&" "&[1]IFE!B31 -> 6,5x12 plg
A11: =[1]IFE!B169 -> 65 pies, 8.-plg DC | C11: =[1]IFE!B175 -> 0 | E11: Total Circulating Volume | H11: ="Pump Capacity "&[1]IFE!B57 -> Pump Capacity gal/emb | I11: =[1]IFE!B182 -> 5.016 | J11: =[1]IFE!B183 -> 5.016
A12: =[1]IFE!B170 -> 34 pies, 8.-plg JAR | C12: =[1]IFE!B176 -> 0 | E12: =[1]IFE!$B$179 -> 0 | H12: Pump stk/min | I12: =[1]IFE!G161&"@"&[1]IFE!F161&"%" -> 0@97% | J12: =[1]IFE!G162&"@"&[1]IFE!F162&"%" -> 0@97%
A13: =[1]IFE!B171 -> 96 pies, 8.-plg DC | C13: =[1]IFE!D173 -> 0 | E13: Depth Drilled Last 24hr | H13: Flow Rate | I13: =[1]IFE!B150 -> 0 | J13: =[1]IFE!B33 -> gal/min
A14: =[1]IFE!B172 -> 31 pies, 9.5-plg DC | C14: =[1]IFE!D174 -> 0 | E14: =[1]IFE!$BE$86 -> 0 | F14: =[1]IFE!$B$30 -> pies | H14: Pump Pressure | I14: =[1]IFE!B152 -> 0 | J14: =[1]IFE!B36 -> psi
A15: ="Nozzles "&[1]IFE!B139&IF([1]IFE!B142=0,"","x"&[1]IFE!B142)&IF([1]IFE!B140=0,"","/"&[1]IFE!B140&IF([1]IFE!B143=0,"","x"&[1]IFE!B143))&IF([1]IFE!B141=0,"", "/"&[1]IFE!B141&IF([1]IFE!B144=0,"","x"&[1]IFE!B144))&" "&[1]IFE!B34 -> Nozzles 0 1/32 plg | C15: =[1]IFE!D175 -> 0 | E15: Volume Drilled Last 24hr | H15: Bottoms Up | I15: =[1]IFE!B186 -> 0
A16: ="Bit "&[1]IFE!B136 & "-" & [1]IFE!B31&" "&[1]IFE!B137 -> Bit 26-plg 0 | C16: =[1]IFE!D176 -> 0 | E16: =[1]IFE!$D$148 -> 0 | F16: =[1]IFE!$B$32 -> bbl | H16: Total Circulation | I16: =[1]IFE!B187 -> 0
A17: MUD PROPERTIES | G17: PRODUCTS USED Last 24 hr
A18: Sample From | C18: =CONCATENATE(TEXT([1]IFE!C77," ")&" "&TEXT([1]IFE!C78,"H:MM")) -> TK 1 12:00 | D18: =CONCATENATE(TEXT([1]IFE!D77," ")&" "&TEXT([1]IFE!D78,"H:MM")) -> 0:00 | E18: =CONCATENATE(TEXT([1]IFE!E77," ")&" "&TEXT([1]IFE!E78,"H:MM")) -> TK 3 12:00 | F18: =CONCATENATE(TEXT([1]IFE!F77," ")&" "&TEXT([1]IFE!F78,"H:MM")) -> TK 3 0:00 | G18: Products | I18: Size | J18: Amount
A19: FlowLine Temp | B19: =[1]IFE!B40 -> °F | C19: =[1]IFE!C79 -> 0 | D19: =[1]IFE!D79 -> 0 | E19: =[1]IFE!E79 -> 0 | F19: =[1]IFE!F79 -> 0 | G19: =[1]IFE!B313 -> ENGINEERING SERVICE | I19: =[1]IFE!C313 -> 1. EA | J19: =[1]IFE!D313 -> 2
A20: Depth/TVD | B20: =[1]IFE!B30 -> pies | C20: =CONCATENATE(TEXT([1]IFE!C80,"#")&"/"&TEXT([1]IFE!C81,"#")) -> 563/563 | D20: =CONCATENATE(TEXT([1]IFE!D80,"#")&"/"&TEXT([1]IFE!D81,"#")) -> 563/563 | E20: =CONCATENATE(TEXT([1]IFE!E80,"#")&"/"&TEXT([1]IFE!E81,"#")) -> 563/563 | F20: =CONCATENATE(TEXT([1]IFE!F80,"#")&"/"&TEXT([1]IFE!F81,"#")) -> 563/563 | G20: =[1]IFE!B314 -> BENTONITE WYOMING | I20: =[1]IFE!C314 -> 100. LB BG | J20: =[1]IFE!D314 -> 1
A21: Mud Weight /Temp | B21: =[1]IFE!B39 -> lb/gal | C21: =CONCATENATE(TEXT([1]IFE!C82,"#.0")&"@"&TEXT([1]IFE!C83,"#")) -> 9.1@85 | D21: =CONCATENATE(TEXT([1]IFE!D82,"#.0")&"@"&TEXT([1]IFE!D83,"#")) -> 9.1@85 | E21: =CONCATENATE(TEXT([1]IFE!E82,"#.0")&"@"&TEXT([1]IFE!E83,"#")) -> 14.0@85 | F21: =CONCATENATE(TEXT([1]IFE!F82,"#.0")&"@"&TEXT([1]IFE!F83,"#")) -> 14.0@85 | G21: =[1]IFE!B315 -> DUO-VIS | I21: =[1]IFE!C315 -> 25. KG BG | J21: =[1]IFE!D315 -> 5
A22: Funnel Viscosity | B22: =[1]IFE!B43 -> s/ct | C22: =[1]IFE!C84 -> 55 | D22: =[1]IFE!D84 -> 55 | E22: =[1]IFE!E84 -> 80 | F22: =[1]IFE!F84 -> 80 | G22: =[1]IFE!B316 -> 0 | I22: =[1]IFE!C316 -> 0 | J22: =[1]IFE!D316 -> 0
A23: Rheology Temp | B23: =[1]IFE!B40 -> °F | C23: =[1]IFE!C85 -> 120 | D23: =[1]IFE!D85 -> 120 | E23: =[1]IFE!E85 -> 120 | F23: =[1]IFE!F85 -> 120 | G23: =[1]IFE!B317 -> 0 | I23: =[1]IFE!C317 -> 0 | J23: =[1]IFE!D317 -> 0
A24: R600/R300 | C24: =CONCATENATE(TEXT([1]IFE!C86,"#")&"/"&TEXT([1]IFE!C87,"#")) -> 38/27 | D24: =CONCATENATE(TEXT([1]IFE!D86,"#")&"/"&TEXT([1]IFE!D87,"#")) -> 38/27 | E24: =CONCATENATE(TEXT([1]IFE!E86,"#")&"/"&TEXT([1]IFE!E87,"#")) -> 130/81 | F24: =CONCATENATE(TEXT([1]IFE!F86,"#")&"/"&TEXT([1]IFE!F87,"#")) -> 130/81 | G24: =[1]IFE!B318 -> 0 | I24: =[1]IFE!C318 -> 0 | J24: =[1]IFE!D318 -> 0
A25: R200/R100 | C25: =CONCATENATE(TEXT([1]IFE!C88,"#")&"/"&TEXT([1]IFE!C89,"#")) -> 23/18 | D25: =CONCATENATE(TEXT([1]IFE!D88,"#")&"/"&TEXT([1]IFE!D89,"#")) -> 23/18 | E25: =CONCATENATE(TEXT([1]IFE!E88,"#")&"/"&TEXT([1]IFE!E89,"#")) -> 61/39 | F25: =CONCATENATE(TEXT([1]IFE!F88,"#")&"/"&TEXT([1]IFE!F89,"#")) -> 61/39 | G25: =[1]IFE!B319 -> 0 | I25: =[1]IFE!C319 -> 0 | J25: =[1]IFE!D319 -> 0
A26: R6/R3 | C26: =CONCATENATE(TEXT([1]IFE!C90,"#")&"/"&TEXT([1]IFE!C91,"#")) -> 11/10 | D26: =CONCATENATE(TEXT([1]IFE!D90,"#")&"/"&TEXT([1]IFE!D91,"#")) -> 11/10 | E26: =CONCATENATE(TEXT([1]IFE!E90,"#")&"/"&TEXT([1]IFE!E91,"#")) -> 10/8 | F26: =CONCATENATE(TEXT([1]IFE!F90,"#")&"/"&TEXT([1]IFE!F91,"#")) -> 10/8 | G26: =[1]IFE!B320 -> 0 | I26: =[1]IFE!C320 -> 0 | J26: =[1]IFE!D320 -> 0
A27: PV | B27: =[1]IFE!B41 -> cP | C27: =[1]IFE!C92 -> 11 | D27: =[1]IFE!D92 -> 11 | E27: =[1]IFE!E92 -> 49 | F27: =[1]IFE!F92 -> 49 | G27: =[1]IFE!B321 -> 0 | I27: =[1]IFE!C321 -> 0 | J27: =[1]IFE!D321 -> 0
A28: YP | B28: =[1]IFE!B42 -> lb/100p² | C28: =[1]IFE!C93 -> 16 | D28: =[1]IFE!D93 -> 16 | E28: =[1]IFE!E93 -> 32 | F28: =[1]IFE!F93 -> 32 | G28: =[1]IFE!B322 -> 0 | I28: =[1]IFE!C322 -> 0 | J28: =[1]IFE!D322 -> 0
A29: 10s/10m/30m Gel | B29: =[1]IFE!B42 -> lb/100p² | C29: =CONCATENATE(TEXT([1]IFE!C94,"#")&"/"&(TEXT([1]IFE!C95,"#")&"/"&TEXT([1]IFE!C96,"#"))) -> 11/15/ | D29: =CONCATENATE(TEXT([1]IFE!D94,"#")&"/"&(TEXT([1]IFE!D95,"#")&"/"&TEXT([1]IFE!D96,"#"))) -> 11/15/ | E29: =CONCATENATE(TEXT([1]IFE!E94,"#")&"/"&(TEXT([1]IFE!E95,"#")&"/"&TEXT([1]IFE!E96,"#"))) -> 12/18/ | F29: =CONCATENATE(TEXT([1]IFE!F94,"#")&"/"&(TEXT([1]IFE!F95,"#")&"/"&TEXT([1]IFE!F96,"#"))) -> 12/18/ | G29: =[1]IFE!B323 -> 0 | I29: =[1]IFE!C323 -> 0 | J29: =[1]IFE!D323 -> 0
A30: API Fluid Loss | B30: =[1]IFE!D57 -> cc/30min | C30: =[1]IFE!C97 -> 0 | D30: =[1]IFE!D97 -> 0 | E30: =[1]IFE!E97 -> 0 | F30: =[1]IFE!F97 -> 0 | G30: =[1]IFE!B324 -> 0 | I30: =[1]IFE!C324 -> 0 | J30: =[1]IFE!D324 -> 0
A31: HTHP Fluid Loss | B31: =[1]IFE!D57 -> cc/30min | C31: =CONCATENATE(TEXT([1]IFE!Z538,"#.0")&"@"&TEXT([1]IFE!C99,"#")) -> .0@ | D31: =CONCATENATE(TEXT([1]IFE!D98,"#.0")&"@"&TEXT([1]IFE!D99,"#")) -> .0@ | E31: =CONCATENATE(TEXT([1]IFE!E98,"#.0")&"@"&TEXT([1]IFE!E99,"#")) -> .0@ | F31: =CONCATENATE(TEXT([1]IFE!Z661,"#.0")&"@"&TEXT([1]IFE!F99,"#")) -> .0@ | G31: =[1]IFE!B325 -> 0 | I31: =[1]IFE!C325 -> 0 | J31: =[1]IFE!D325 -> 0
A32: Cake APT/HT | B32: =[1]IFE!B34 -> 1/32 plg | C32: =CONCATENATE(TEXT([1]IFE!C100,"#")&"/"&TEXT([1]IFE!Z541,"#")) -> / | D32: =CONCATENATE(TEXT([1]IFE!D100,"#")&"/"&TEXT([1]IFE!D101,"#")) -> / | E32: =CONCATENATE(TEXT([1]IFE!E100,"#")&"/"&TEXT([1]IFE!E101,"#")) -> / | F32: =CONCATENATE(TEXT([1]IFE!F100,"#")&"/"&TEXT([1]IFE!Z664,"#")) -> / | G32: =[1]IFE!B326 -> 0 | I32: =[1]IFE!C326 -> 0 | J32: =[1]IFE!D326 -> 0
A33: Solids | B33: =[1]IFE!D59 -> %Vol | C33: =[1]IFE!C102 -> 4.2 | D33: =[1]IFE!D102 -> 4.2 | E33: =[1]IFE!E102 -> 22 | F33: =[1]IFE!F102 -> 22 | G33: =[1]IFE!B327 -> 0 | I33: =[1]IFE!C327 -> 0 | J33: =[1]IFE!D327 -> 0
A34: Oil/Water | B34: =[1]IFE!D59 -> %Vol | C34: =CONCATENATE(TEXT([1]IFE!C103,"#")&"/"&TEXT([1]IFE!C104,"#")) -> /96 | D34: =CONCATENATE(TEXT([1]IFE!D103,"#")&"/"&TEXT([1]IFE!D104,"#")) -> /96 | E34: =CONCATENATE(TEXT([1]IFE!E103,"#")&"/"&TEXT([1]IFE!E104,"#")) -> /78 | F34: =CONCATENATE(TEXT([1]IFE!F103,"#")&"/"&TEXT([1]IFE!F104,"#")) -> /78 | G34: SOLIDS CONTROL EQUIPMENT Last 24 hr
A35: Sand | B35: =[1]IFE!D59 -> %Vol | C35: =[1]IFE!C105 -> 0 | D35: =[1]IFE!D105 -> 0 | E35: =[1]IFE!E105 -> 0 | F35: =[1]IFE!F105 -> 0 | G35: Type | I35: Model/Size | J35: Hrs Used
A36: MBT | B36: =[1]IFE!B44 -> lb/bbl | C36: =[1]IFE!C106 -> 20 | D36: =[1]IFE!D106 -> 20 | E36: =[1]IFE!E106 -> 15 | F36: =[1]IFE!F106 -> 15 | G36: =[1]IFE!$B220 -> DERRICK SHEKER 1 | I36: =[1]IFE!$C220 -> 2X100 - 2X140 | J36: =[1]IFE!$D220 -> 0
A37: pH / Temp | C37: =CONCATENATE(TEXT([1]IFE!C107,"#.0")&"@"&TEXT([1]IFE!C108,"#")) -> 10.0@85 | D37: =CONCATENATE(TEXT([1]IFE!D107,"#.0")&"@"&TEXT([1]IFE!D108,"#")) -> 10.0@85 | E37: =CONCATENATE(TEXT([1]IFE!E107,"#.0")&"@"&TEXT([1]IFE!E108,"#")) -> 10.5@85 | F37: =CONCATENATE(TEXT([1]IFE!F107,"#.0")&"@"&TEXT([1]IFE!F108,"#")) -> 10.5@85 | G37: =[1]IFE!$B221 -> DERRICK SHAKER 2 | I37: =[1]IFE!$C221 -> 2X100 - 2X140 | J37: =[1]IFE!$D221 -> 0
A38: Alkal Mud (Pm) | C38: =[1]IFE!C109 -> 0.8 | D38: =[1]IFE!D109 -> 0.8 | E38: =[1]IFE!E109 -> 0 | F38: =[1]IFE!F109 -> 0 | G38: =[1]IFE!$B222 -> DERRICK SHAKER 3 | I38: =[1]IFE!$C222 -> 2X100 - 2X140 | J38: =[1]IFE!$D222 -> 0
A39: Pf/Mf | B39: =[1]IFE!D31 -> 0 | C39: =CONCATENATE(TEXT([1]IFE!C110,"#.00"),"/",TEXT([1]IFE!C111,"#.00")) -> .20/.60 | D39: =CONCATENATE(TEXT([1]IFE!D110,"#.00"),"/",TEXT([1]IFE!D111,"#.00")) -> .20/.60 | E39: =CONCATENATE(TEXT([1]IFE!E110,"#.00")&"/"&TEXT([1]IFE!E111,"#.00")) -> .00/.00 | F39: =CONCATENATE(TEXT([1]IFE!F110,"#.00")&"/"&TEXT([1]IFE!F111,"#.00")) -> .00/.00 | G39: =[1]IFE!$B223 -> MOD 312 / 10T2 w/o pump | I39: =[1]IFE!$C223 -> 4 X 200 | J39: =[1]IFE!$D223 -> 0
A40: Chlorides | B40: =[1]IFE!D58 -> mg/L | C40: =[1]IFE!C112 -> 0 | D40: =[1]IFE!D112 -> 0 | E40: =[1]IFE!E112 -> 0 | F40: =[1]IFE!F112 -> 0 | G40: =[1]IFE!$B224 -> 0 | I40: =[1]IFE!$C224 -> 0 | J40: =[1]IFE!$D224 -> 0
A41: Hardness (Ca++) | C41: =[1]IFE!C113 -> 80 | D41: =[1]IFE!D113 -> 80 | E41: =[1]IFE!E113 -> 0 | F41: =[1]IFE!F113 -> 0 | G41: =[1]IFE!$B225 -> 0 | I41: =[1]IFE!$C225 -> 0 | J41: =[1]IFE!$D225 -> 0
...

Sheet Synthetic-Based Mud
J2: ="SYNTHETIC-BASED MUD REPORT No. "&[1]IFE!B166&" " -> SYNTHETIC-BASED MUD REPORT No. 9
A3: Operator : | B3: =[1]IFE!B6 -> Cardon IV | D3: Field/Area : | E3: =[1]IFE!B9 -> Golfo de Venezuela | H3: Depth/TVD : | I3: =[1]IFE!B120&" "&[1]IFE!B30&" /" -> 563 pies / | J3: =[1]IFE!B121&" "&[1]IFE!B30 -> 563 pies
A4: Report For : | B4: =[1]IFE!B125 -> Gerrit Ham / Jhony Quintero | D4: Description : | E4: =[1]IFE!B10 -> Exploratory | H4: Date : | I4: =[1]IFE!B119 -> 39989
A5: Well Name : | B5: =[1]IFE!B8 -> Perla-1X | D5: Location : | E5: =[1]IFE!B11 -> Offshore | H5: Spud Date : | I5: =[1]IFE!B5 -> 39981
A6: Contractor: | B6: =[1]IFE!B15 -> Ensco | D6: Water Depth : | E6: =[1]IFE!B16&" "&[1]IFE!B30 -> 202 pies | H6: Mud Type : | I6: =[1]IFE!B124 -> Agua de mar / HI VIS
A7: Report For : | B7: =[1]IFE!B126 -> Ricky Otwell | D7: Rig Name : | E7: =[1]IFE!Z981 -> 68 | H7: Activity : | I7: =[1]IFE!B123 -> Bajando Tuberia
A8: DRILLING ASSEMBLY | C8: CASING (*TVD) | E8: ="MUD VOLUME" & " ("& [1]IFE!B32&")" -> MUD VOLUME (bbl) | G8: CIRCULATION DATA
A9: =[1]IFE!B167 -> pies, 5.5-plg DP | C9: =[1]IFE!B173 -> 30.-plg @563 pies (563 TVD) | E9: Hole | F9: Active Pits | H9: Pump Make | I9: =[1]IFE!B161 -> NATIONAL 12P-160 | J9: =[1]IFE!B162 -> NATIONAL 12P-160
A10: =[1]IFE!B168 -> 372 pies, 5.5-plg HWDP | C10: =[1]IFE!B174 -> 0 | E10: =[1]IFE!B177 -> 429 | F10: =[1]IFE!B178 -> 0 | H10: Pump Liner x Stk | I10: =[1]IFE!C161&"x"&[1]IFE!D161&" "&[1]IFE!B31 -> 6,5x12 plg | J10: =[1]IFE!C162&"x"&[1]IFE!D162&" "&[1]IFE!B31 -> 6,5x12 plg
A11: =[1]IFE!B169 -> 65 pies, 8.-plg DC | C11: =[1]IFE!B175 -> 0 | E11: Total Circulating Volume | H11: ="Pump Capacity "&[1]IFE!B57 -> Pump Capacity gal/emb | I11: =[1]IFE!B182 -> 5.016 | J11: =[1]IFE!B183 -> 5.016
A12: =[1]IFE!B170 -> 34 pies, 8.-plg JAR | C12: =[1]IFE!B176 -> 0 | E12: =[1]IFE!$B$179 -> 0 | H12: Pump stk/min | I12: =[1]IFE!G161&"@"&[1]IFE!F161&"%" -> 0@97% | J12: =[1]IFE!G162&"@"&[1]IFE!F162&"%" -> 0@97%
A13: =[1]IFE!B171 -> 96 pies, 8.-plg DC | C13: =[1]IFE!D173 -> 0 | E13: Depth Drilled Last 24hr | H13: Flow Rate | I13: =[1]IFE!B150 -> 0 | J13: =[1]IFE!B33 -> gal/min
A14: =[1]IFE!B172 -> 31 pies, 9.5-plg DC | C14: =[1]IFE!D174 -> 0 | E14: =[1]IFE!$BE$86 -> 0 | F14: =[1]IFE!$B$30 -> pies | H14: Pump Pressure | I14: =[1]IFE!B152 -> 0 | J14: =[1]IFE!B36 -> psi
A15: ="Nozzles "&[1]IFE!B139&IF([1]IFE!B142=0,"","x"&[1]IFE!B142)&IF([1]IFE!B140=0,"","/"&[1]IFE!B140&IF([1]IFE!B143=0,"","x"&[1]IFE!B143))&IF([1]IFE!B141=0,"", "/"&[1]IFE!B141&IF([1]IFE!B144=0,"","x"&[1]IFE!B144))&" "&[1]IFE!B34 -> Nozzles 0 1/32 plg | C15: =[1]IFE!D175 -> 0 | E15: Volume Drilled Last 24hr | H15: Bottoms Up | I15: =[1]IFE!B186 -> 0
A16: ="Bit "&[1]IFE!B136 & "-" & [1]IFE!B31&" "&[1]IFE!B137 -> Bit 26-plg 0 | C16: =[1]IFE!D176 -> 0 | E16: =[1]IFE!$D$148 -> 0 | F16: =[1]IFE!$B$32 -> bbl | H16: Total Circulation | I16: =[1]IFE!B187 -> 0
A17: MUD PROPERTIES | G17: PRODUCTS USED Last 24 hr
A18: Sample From | C18: =CONCATENATE(TEXT([1]IFE!C77," ")&" "&TEXT([1]IFE!C78,"H:MM")) -> TK 1 12:00 | D18: =CONCATENATE(TEXT([1]IFE!D77," ")&" "&TEXT([1]IFE!D78,"H:MM")) -> 0:00 | E18: =CONCATENATE(TEXT([1]IFE!E77," ")&" "&TEXT([1]IFE!E78,"H:MM")) -> TK 3 12:00 | F18: =CONCATENATE(TEXT([1]IFE!F77," ")&" "&TEXT([1]IFE!F78,"H:MM")) -> TK 3 0:00 | G18: Products | I18: Size | J18: Amount
A19: FlowLine Temp | B19: =[1]IFE!B40 -> °F | C19: =[1]IFE!C79 -> 0 | D19: =[1]IFE!D79 -> 0 | E19: =[1]IFE!E79 -> 0 | F19: =[1]IFE!F79 -> 0 | G19: =[1]IFE!B313 -> ENGINEERING SERVICE | I19: =[1]IFE!C313 -> 1. EA | J19: =[1]IFE!D313 -> 2
A20: Depth/TVD | B20: =[1]IFE!B30 -> pies | C20: =CONCATENATE(TEXT([1]IFE!C80,"#")&"/"&TEXT([1]IFE!C81,"#")) -> 563/563 | D20: =CONCATENATE(TEXT([1]IFE!D80,"#")&"/"&TEXT([1]IFE!D81,"#")) -> 563/563 | E20: =CONCATENATE(TEXT([1]IFE!E80,"#")&"/"&TEXT([1]IFE!E81,"#")) -> 563/563 | F20: =CONCATENATE(TEXT([1]IFE!F80,"#")&"/"&TEXT([1]IFE!F81,"#")) -> 563/563 | G20: =[1]IFE!B314 -> BENTONITE WYOMING | I20: =[1]IFE!C314 -> 100. LB BG | J20: =[1]IFE!D314 -> 1
A21: Mud Weight | B21: =[1]IFE!B39 -> lb/gal | C21: =CONCATENATE(TEXT([1]IFE!C82,"#.0")&"@"&TEXT([1]IFE!C83,"#")) -> 9.1@85 | D21: =CONCATENATE(TEXT([1]IFE!D82,"#.0")&"@"&TEXT([1]IFE!D83,"#")) -> 9.1@85 | E21: =CONCATENATE(TEXT([1]IFE!E82,"#.0")&"@"&TEXT([1]IFE!E83,"#")) -> 14.0@85 | F21: =CONCATENATE(TEXT([1]IFE!F82,"#.0")&"@"&TEXT([1]IFE!F83,"#")) -> 14.0@85 | G21: =[1]IFE!B315 -> DUO-VIS | I21: =[1]IFE!C315 -> 25. KG BG | J21: =[1]IFE!D315 -> 5
A22: Funnel Viscosity | B22: =[1]IFE!B43 -> s/ct | C22: =[1]IFE!C84 -> 55 | D22: =[1]IFE!D84 -> 55 | E22: =[1]IFE!E84 -> 80 | F22: =[1]IFE!F84 -> 80 | G22: =[1]IFE!B316 -> 0 | I22: =[1]IFE!C316 -> 0 | J22: =[1]IFE!D316 -> 0
A23: Rheology Temp | B23: =[1]IFE!B40 -> °F | C23: =[1]IFE!C85 -> 120 | D23: =[1]IFE!D85 -> 120 | E23: =[1]IFE!E85 -> 120 | F23: =[1]IFE!F85 -> 120 | G23: =[1]IFE!B317 -> 0 | I23: =[1]IFE!C317 -> 0 | J23: =[1]IFE!D317 -> 0
A24: R600/R300 | C24: =CONCATENATE(TEXT([1]IFE!C86,"#")&"/"&TEXT([1]IFE!C87,"#")) -> 38/27 | D24: =CONCATENATE(TEXT([1]IFE!D86,"#")&"/"&TEXT([1]IFE!D87,"#")) -> 38/27 | E24: =CONCATENATE(TEXT([1]IFE!E86,"#")&"/"&TEXT([1]IFE!E87,"#")) -> 130/81 | F24: =CONCATENATE(TEXT([1]IFE!F86,"#")&"/"&TEXT([1]IFE!F87,"#")) -> 130/81 | G24: =[1]IFE!B318 -> 0 | I24: =[1]IFE!C318 -> 0 | J24: =[1]IFE!D318 -> 0
A25: R200/R100 | C25: =CONCATENATE(TEXT([1]IFE!C88,"#")&"/"&TEXT([1]IFE!C89,"#")) -> 23/18 | D25: =CONCATENATE(TEXT([1]IFE!D88,"#")&"/"&TEXT([1]IFE!D89,"#")) -> 23/18 | E25: =CONCATENATE(TEXT([1]IFE!E88,"#")&"/"&TEXT([1]IFE!E89,"#")) -> 61/39 | F25: =CONCATENATE(TEXT([1]IFE!F88,"#")&"/"&TEXT([1]IFE!F89,"#")) -> 61/39 | G25: =[1]IFE!B319 -> 0 | I25: =[1]IFE!C319 -> 0 | J25: =[1]IFE!D319 -> 0
A26: R6/R3 | C26: =CONCATENATE(TEXT([1]IFE!C90,"#")&"/"&TEXT([1]IFE!C91,"#")) -> 11/10 | D26: =CONCATENATE(TEXT([1]IFE!D90,"#")&"/"&TEXT([1]IFE!D91,"#")) -> 11/10 | E26: =CONCATENATE(TEXT([1]IFE!E90,"#")&"/"&TEXT([1]IFE!E91,"#")) -> 10/8 | F26: =CONCATENATE(TEXT([1]IFE!F90,"#")&"/"&TEXT([1]IFE!F91,"#")) -> 10/8 | G26: =[1]IFE!B320 -> 0 | I26: =[1]IFE!C320 -> 0 | J26: =[1]IFE!D320 -> 0
A27: PV | B27: =[1]IFE!B41 -> cP | C27: =[1]IFE!C92 -> 11 | D27: =[1]IFE!D92 -> 11 | E27: =[1]IFE!E92 -> 49 | F27: =[1]IFE!F92 -> 49 | G27: =[1]IFE!B321 -> 0 | I27: =[1]IFE!C321 -> 0 | J27: =[1]IFE!D321 -> 0
A28: YP | B28: =[1]IFE!B42 -> lb/100p² | C28: =[1]IFE!C93 -> 16 | D28: =[1]IFE!D93 -> 16 | E28: =[1]IFE!E93 -> 32 | F28: =[1]IFE!F93 -> 32 | G28: =[1]IFE!B322 -> 0 | I28: =[1]IFE!C322 -> 0 | J28: =[1]IFE!D322 -> 0
A29: 10s/10m/30m Gel | B29: =[1]IFE!B42 -> lb/100p² | C29: =CONCATENATE(TEXT([1]IFE!C94,"#")&"/"&(TEXT([1]IFE!C95,"#")&"/"&TEXT([1]IFE!C96,"#"))) -> 11/15/ | D29: =CONCATENATE(TEXT([1]IFE!D94,"#")&"/"&(TEXT([1]IFE!D95,"#")&"/"&TEXT([1]IFE!D96,"#"))) -> 11/15/ | E29: =CONCATENATE(TEXT([1]IFE!E94,"#")&"/"&(TEXT([1]IFE!E95,"#")&"/"&TEXT([1]IFE!E96,"#"))) -> 12/18/ | F29: =CONCATENATE(TEXT([1]IFE!F94,"#")&"/"&(TEXT([1]IFE!F95,"#")&"/"&TEXT([1]IFE!F96,"#"))) -> 12/18/ | G29: =[1]IFE!B323 -> 0 | I29: =[1]IFE!C323 -> 0 | J29: =[1]IFE!D323 -> 0
A30: API Fluid Loss | B30: =[1]IFE!D57 -> cc/30min | C30: =[1]IFE!C97 -> 0 | D30: =[1]IFE!D97 -> 0 | E30: =[1]IFE!E97 -> 0 | F30: =[1]IFE!F97 -> 0 | G30: =[1]IFE!B324 -> 0 | I30: =[1]IFE!C324 -> 0 | J30: =[1]IFE!D324 -> 0
A31: HTHP Fluid Loss | B31: =[1]IFE!D57 -> cc/30min | C31: =CONCATENATE(TEXT([1]IFE!C98,"#.0")&"@"&TEXT([1]IFE!C99,"#")) -> .0@ | D31: =CONCATENATE(TEXT([1]IFE!D98,"#.0")&"@"&TEXT([1]IFE!D99,"#")) -> .0@ | E31: =CONCATENATE(TEXT([1]IFE!E98,"#.0")&"@"&TEXT([1]IFE!E99,"#")) -> .0@ | F31: =CONCATENATE(TEXT([1]IFE!F98,"#.0")&"@"&TEXT([1]IFE!F99,"#")) -> .0@ | G31: =[1]IFE!B325 -> 0 | I31: =[1]IFE!C325 -> 0 | J31: =[1]IFE!D325 -> 0
A32: Cake APT/HT | B32: =[1]IFE!B34 -> 1/32 plg | C32: =CONCATENATE(TEXT([1]IFE!C100,"#")&"/"&TEXT([1]IFE!C101,"#")) -> / | D32: =CONCATENATE(TEXT([1]IFE!D100,"#")&"/"&TEXT([1]IFE!D101,"#")) -> / | E32: =CONCATENATE(TEXT([1]IFE!E100,"#")&"/"&TEXT([1]IFE!E101,"#")) -> / | F32: =CONCATENATE(TEXT([1]IFE!F100,"#")&"/"&TEXT([1]IFE!F101,"#")) -> / | G32: =[1]IFE!B326 -> 0 | I32: =[1]IFE!C326 -> 0 | J32: =[1]IFE!D326 -> 0
A33: Unc Ret Solids | B33: =[1]IFE!D59 -> %Vol | C33: =[1]IFE!C102 -> 4.2 | D33: =[1]IFE!D102 -> 4.2 | E33: =[1]IFE!E102 -> 22 | F33: =[1]IFE!F102 -> 22 | G33: =[1]IFE!B327 -> 0 | I33: =[1]IFE!C327 -> 0 | J33: =[1]IFE!D327 -> 0
A34: Correct Solids | B34: =[1]IFE!D59 -> %Vol | C34: =[1]IFE!C103 -> 0 | D34: =[1]IFE!D103 -> 0 | E34: =[1]IFE!E103 -> 0 | F34: =[1]IFE!F103 -> 0 | G34: SOLIDS CONTROL EQUIPMENT Last 24 hr
A35: Synthetic | B35: =[1]IFE!D59 -> %Vol | C35: =[1]IFE!C104 -> 95.8 | D35: =[1]IFE!D104 -> 95.8 | E35: =[1]IFE!E104 -> 78 | F35: =[1]IFE!F104 -> 78 | G35: Type | I35: Model/Size | J35: Hrs Used
A36: Uncorr Water | B36: =[1]IFE!D59 -> %Vol | C36: =[1]IFE!C105 -> 0 | D36: =[1]IFE!D105 -> 0 | E36: =[1]IFE!E105 -> 0 | F36: =[1]IFE!F105 -> 0 | G36: =[1]IFE!$B220 -> DERRICK SHEKER 1 | I36: =[1]IFE!$C220 -> 2X100 - 2X140 | J36: =[1]IFE!$D220 -> 0
A37: Synthetic/Water Ratio | C37: =CONCATENATE(TEXT([1]IFE!C106,"#")&"/"&TEXT([1]IFE!C107,"#")) -> 20/10 | D37: =CONCATENATE(TEXT([1]IFE!D106,"#")&"/"&TEXT([1]IFE!D107,"#")) -> 20/10 | E37: =CONCATENATE(TEXT([1]IFE!E106,"#")&"/"&TEXT([1]IFE!E107,"#")) -> 15/11 | F37: =CONCATENATE(TEXT([1]IFE!F106,"#")&"/"&TEXT([1]IFE!F107,"#")) -> 15/11 | G37: =[1]IFE!$B221 -> DERRICK SHAKER 2 | I37: =[1]IFE!$C221 -> 2X100 - 2X140 | J37: =[1]IFE!$D221 -> 0
A38: Alkal Mud (Psm) | C38: =[1]IFE!C108 -> 85 | D38: =[1]IFE!D108 -> 85 | E38: =[1]IFE!E108 -> 85 | F38: =[1]IFE!F108 -> 85 | G38: =[1]IFE!$B222 -> DERRICK SHAKER 3 | I38: =[1]IFE!$C222 -> 2X100 - 2X140 | J38: =[1]IFE!$D222 -> 0
A39: Cl- Whole Mud | B39: =[1]IFE!D58 -> mg/L | C39: =[1]IFE!C109 -> 0.8 | D39: =[1]IFE!D109 -> 0.8 | E39: =[1]IFE!E109 -> 0 | F39: =[1]IFE!F109 -> 0 | G39: =[1]IFE!$B223 -> MOD 312 / 10T2 w/o pump | I39: =[1]IFE!$C223 -> 4 X 200 | J39: =[1]IFE!$D223 -> 0
A40: Salt | B40: =[1]IFE!D60 -> %Wt | C40: =[1]IFE!C110 -> 0.2 | D40: =[1]IFE!D110 -> 0.2 | E40: =[1]IFE!E110 -> 0 | F40: =[1]IFE!F110 -> 0 | G40: =[1]IFE!$B224 -> 0 | I40: =[1]IFE!$C224 -> 0 | J40: =[1]IFE!$D224 -> 0
A41: Lime | B41: =[1]IFE!B44 -> lb/bbl | C41: =[1]IFE!C111 -> 0.6 | D41: =[1]IFE!D111 -> 0.6 | E41: =[1]IFE!E111 -> 0 | F41: =[1]IFE!F111 -> 0 | G41: =[1]IFE!$B225 -> 0 | I41: =[1]IFE!$C225 -> 0 | J41: =[1]IFE!$D225 -> 0
...

Sheet OBM Check
J2: ="OIL-BASED MUD REPORT No. "&[1]IFE!B166&" " -> OIL-BASED MUD REPORT No. 9
A3: Operator : | B3: =[1]IFE!B6 -> Cardon IV | D3: Field/Area : | E3: =[1]IFE!B9 -> Golfo de Venezuela | H3: Depth/TVD : | I3: =[1]IFE!B120&" "&[1]IFE!B30&" /" -> 563 pies / | J3: =[1]IFE!B121&" "&[1]IFE!B30 -> 563 pies
A4: Report For : | B4: =[1]IFE!B125 -> Gerrit Ham / Jhony Quintero | D4: Description : | E4: =[1]IFE!B10 -> Exploratory | H4: Date : | I4: =[1]IFE!B119 -> 39989
A5: Well Name : | B5: =[1]IFE!B8 -> Perla-1X | D5: Location : | E5: =[1]IFE!B11 -> Offshore | H5: Spud Date : | I5: =[1]IFE!B5 -> 39981
A6: Contractor: | B6: =[1]IFE!B15 -> Ensco | D6: Water Depth : | E6: =[1]IFE!B16&" "&[1]IFE!B30 -> 202 pies | H6: Mud Type : | I6: =[1]IFE!B124 -> Agua de mar / HI VIS
A7: Report For : | B7: =[1]IFE!B126 -> Ricky Otwell | D7: Rig Name : | E7: =[1]IFE!Z981 -> 68 | H7: Activity : | I7: =[1]IFE!B123 -> Bajando Tuberia
A8: DRILLING ASSEMBLY | C8: CASING (*TVD) | E8: ="MUD VOLUME" & " ("& [1]IFE!B32&")" -> MUD VOLUME (bbl) | G8: CIRCULATION DATA
A9: =[1]IFE!B167 -> pies, 5.5-plg DP | C9: =[1]IFE!B173 -> 30.-plg @563 pies (563 TVD) | E9: Hole | F9: Active Pits | H9: Pump Make | I9: =[1]IFE!B161 -> NATIONAL 12P-160 | J9: =[1]IFE!B162 -> NATIONAL 12P-160
A10: =[1]IFE!B168 -> 372 pies, 5.5-plg HWDP | C10: =[1]IFE!B174 -> 0 | E10: =[1]IFE!B177 -> 429 | F10: =[1]IFE!B178 -> 0 | H10: Pump Liner x Stk | I10: =[1]IFE!C161&"x"&[1]IFE!D161&" "&[1]IFE!B31 -> 6,5x12 plg | J10: =[1]IFE!C162&"x"&[1]IFE!D162&" "&[1]IFE!B31 -> 6,5x12 plg
A11: =[1]IFE!B169 -> 65 pies, 8.-plg DC | C11: =[1]IFE!B175 -> 0 | E11: Total Circulating Volume | H11: ="Pump Capacity "&[1]IFE!B57 -> Pump Capacity gal/emb | I11: =[1]IFE!B182 -> 5.016 | J11: =[1]IFE!B183 -> 5.016
A12: =[1]IFE!B170 -> 34 pies, 8.-plg JAR | C12: =[1]IFE!B176 -> 0 | E12: =[1]IFE!$B$179 -> 0 | H12: Pump stk/min | I12: =[1]IFE!G161&"@"&[1]IFE!F161&"%" -> 0@97% | J12: =[1]IFE!G162&"@"&[1]IFE!F162&"%" -> 0@97%
A13: =[1]IFE!B171 -> 96 pies, 8.-plg DC | C13: =[1]IFE!D173 -> 0 | E13: Depth Drilled Last 24hr | H13: Flow Rate | I13: =[1]IFE!B150 -> 0 | J13: =[1]IFE!B33 -> gal/min
A14: =[1]IFE!B172 -> 31 pies, 9.5-plg DC | C14: =[1]IFE!D174 -> 0 | E14: =[1]IFE!$BE$86 -> 0 | F14: =[1]IFE!$B$30 -> pies | H14: Pump Pressure | I14: =[1]IFE!B152 -> 0 | J14: =[1]IFE!B36 -> psi
A15: ="Nozzles "&[1]IFE!B139&IF([1]IFE!B142=0,"","x"&[1]IFE!B142)&IF([1]IFE!B140=0,"","/"&[1]IFE!B140&IF([1]IFE!B143=0,"","x"&[1]IFE!B143))&IF([1]IFE!B141=0,"", "/"&[1]IFE!B141&IF([1]IFE!B144=0,"","x"&[1]IFE!B144))&" "&[1]IFE!B34 -> Nozzles 0 1/32 plg | C15: =[1]IFE!D175 -> 0 | E15: Volume Drilled Last 24hr | H15: Bottoms Up | I15: =[1]IFE!B186 -> 0
A16: ="Bit "&[1]IFE!B136 & "-" & [1]IFE!B31&" "&[1]IFE!B137 -> Bit 26-plg 0 | C16: =[1]IFE!D176 -> 0 | E16: =[1]IFE!$D$148 -> 0 | F16: =[1]IFE!$B$32 -> bbl | H16: Total Circulation | I16: =[1]IFE!B187 -> 0
A17: MUD PROPERTIES | G17: PRODUCTS USED Last 24 hr
A18: Sample From | C18: =CONCATENATE(TEXT([1]IFE!C77," ")&" "&TEXT([1]IFE!C78,"H:MM")) -> TK 1 12:00 | D18: =CONCATENATE(TEXT([1]IFE!D77," ")&" "&TEXT([1]IFE!D78,"H:MM")) -> 0:00 | E18: =CONCATENATE(TEXT([1]IFE!E77," ")&" "&TEXT([1]IFE!E78,"H:MM")) -> TK 3 12:00 | F18: =CONCATENATE(TEXT([1]IFE!F77," ")&" "&TEXT([1]IFE!F78,"H:MM")) -> TK 3 0:00 | G18: Products | I18: Size | J18: Amount
A19: FlowLine Temp | B19: =[1]IFE!B40 -> °F | C19: =[1]IFE!C79 -> 0 | D19: =[1]IFE!D79 -> 0 | E19: =[1]IFE!E79 -> 0 | F19: =[1]IFE!F79 -> 0 | G19: =[1]IFE!B313 -> ENGINEERING SERVICE | I19: =[1]IFE!C313 -> 1. EA | J19: =[1]IFE!D313 -> 2
A20: Depth/TVD | B20: =[1]IFE!B30 -> pies | C20: =CONCATENATE(TEXT([1]IFE!C80,"#")&"/"&TEXT([1]IFE!C81,"#")) -> 563/563 | D20: =CONCATENATE(TEXT([1]IFE!D80,"#")&"/"&TEXT([1]IFE!D81,"#")) -> 563/563 | E20: =CONCATENATE(TEXT([1]IFE!E80,"#")&"/"&TEXT([1]IFE!E81,"#")) -> 563/563 | F20: =CONCATENATE(TEXT([1]IFE!F80,"#")&"/"&TEXT([1]IFE!F81,"#")) -> 563/563 | G20: =[1]IFE!B314 -> BENTONITE WYOMING | I20: =[1]IFE!C314 -> 100. LB BG | J20: =[1]IFE!D314 -> 1
A21: Mud Weight | B21: =[1]IFE!B39 -> lb/gal | C21: =CONCATENATE(TEXT([1]IFE!C82,"#.0")&"@"&TEXT([1]IFE!C83,"#")) -> 9.1@85 | D21: =CONCATENATE(TEXT([1]IFE!D82,"#.0")&"@"&TEXT([1]IFE!D83,"#")) -> 9.1@85 | E21: =CONCATENATE(TEXT([1]IFE!E82,"#.0")&"@"&TEXT([1]IFE!E83,"#")) -> 14.0@85 | F21: =CONCATENATE(TEXT([1]IFE!F82,"#.0")&"@"&TEXT([1]IFE!F83,"#")) -> 14.0@85 | G21: =[1]IFE!B315 -> DUO-VIS | I21: =[1]IFE!C315 -> 25. KG BG | J21: =[1]IFE!D315 -> 5
A22: Funnel Viscosity | B22: =[1]IFE!B43 -> s/ct | C22: =[1]IFE!C84 -> 55 | D22: =[1]IFE!D84 -> 55 | E22: =[1]IFE!E84 -> 80 | F22: =[1]IFE!F84 -> 80 | G22: =[1]IFE!B316 -> 0 | I22: =[1]IFE!C316 -> 0 | J22: =[1]IFE!D316 -> 0
A23: Rheology Temp | B23: =[1]IFE!B40 -> °F | C23: =[1]IFE!C85 -> 120 | D23: =[1]IFE!D85 -> 120 | E23: =[1]IFE!E85 -> 120 | F23: =[1]IFE!F85 -> 120 | G23: =[1]IFE!B317 -> 0 | I23: =[1]IFE!C317 -> 0 | J23: =[1]IFE!D317 -> 0
A24: R600/R300 | C24: =CONCATENATE(TEXT([1]IFE!C86,"#")&"/"&TEXT([1]IFE!C87,"#")) -> 38/27 | D24: =CONCATENATE(TEXT([1]IFE!D86,"#")&"/"&TEXT([1]IFE!D87,"#")) -> 38/27 | E24: =CONCATENATE(TEXT([1]IFE!E86,"#")&"/"&TEXT([1]IFE!E87,"#")) -> 130/81 | F24: =CONCATENATE(TEXT([1]IFE!F86,"#")&"/"&TEXT([1]IFE!F87,"#")) -> 130/81 | G24: =[1]IFE!B318 -> 0 | I24: =[1]IFE!C318 -> 0 | J24: =[1]IFE!D318 -> 0
A25: R200/R100 | C25: =CONCATENATE(TEXT([1]IFE!C88,"#")&"/"&TEXT([1]IFE!C89,"#")) -> 23/18 | D25: =CONCATENATE(TEXT([1]IFE!D88,"#")&"/"&TEXT([1]IFE!D89,"#")) -> 23/18 | E25: =CONCATENATE(TEXT([1]IFE!E88,"#")&"/"&TEXT([1]IFE!E89,"#")) -> 61/39 | F25: =CONCATENATE(TEXT([1]IFE!F88,"#")&"/"&TEXT([1]IFE!F89,"#")) -> 61/39 | G25: =[1]IFE!B319 -> 0 | I25: =[1]IFE!C319 -> 0 | J25: =[1]IFE!D319 -> 0
A26: R6/R3 | C26: =CONCATENATE(TEXT([1]IFE!C90,"#")&"/"&TEXT([1]IFE!C91,"#")) -> 11/10 | D26: =CONCATENATE(TEXT([1]IFE!D90,"#")&"/"&TEXT([1]IFE!D91,"#")) -> 11/10 | E26: =CONCATENATE(TEXT([1]IFE!E90,"#")&"/"&TEXT([1]IFE!E91,"#")) -> 10/8 | F26: =CONCATENATE(TEXT([1]IFE!F90,"#")&"/"&TEXT([1]IFE!F91,"#")) -> 10/8 | G26: =[1]IFE!B320 -> 0 | I26: =[1]IFE!C320 -> 0 | J26: =[1]IFE!D320 -> 0
A27: PV | B27: =[1]IFE!B41 -> cP | C27: =[1]IFE!C92 -> 11 | D27: =[1]IFE!D92 -> 11 | E27: =[1]IFE!E92 -> 49 | F27: =[1]IFE!F92 -> 49 | G27: =[1]IFE!B321 -> 0 | I27: =[1]IFE!C321 -> 0 | J27: =[1]IFE!D321 -> 0
A28: YP | B28: =[1]IFE!B42 -> lb/100p² | C28: =[1]IFE!C93 -> 16 | D28: =[1]IFE!D93 -> 16 | E28: =[1]IFE!E93 -> 32 | F28: =[1]IFE!F93 -> 32 | G28: =[1]IFE!B322 -> 0 | I28: =[1]IFE!C322 -> 0 | J28: =[1]IFE!D322 -> 0
A29: 10s/10m/30m Gel | B29: =[1]IFE!B42 -> lb/100p² | C29: =CONCATENATE(TEXT([1]IFE!C94,"#")&"/"&(TEXT([1]IFE!C95,"#")&"/"&TEXT([1]IFE!C96,"#"))) -> 11/15/ | D29: =CONCATENATE(TEXT([1]IFE!D94,"#")&"/"&(TEXT([1]IFE!D95,"#")&"/"&TEXT([1]IFE!D96,"#"))) -> 11/15/ | E29: =CONCATENATE(TEXT([1]IFE!E94,"#")&"/"&(TEXT([1]IFE!E95,"#")&"/"&TEXT([1]IFE!E96,"#"))) -> 12/18/ | F29: =CONCATENATE(TEXT([1]IFE!F94,"#")&"/"&(TEXT([1]IFE!F95,"#")&"/"&TEXT([1]IFE!F96,"#"))) -> 12/18/ | G29: =[1]IFE!B323 -> 0 | I29: =[1]IFE!C323 -> 0 | J29: =[1]IFE!D323 -> 0
A30: API Fluid Loss | B30: =[1]IFE!D57 -> cc/30min | C30: =[1]IFE!C97 -> 0 | D30: =[1]IFE!D97 -> 0 | E30: =[1]IFE!E97 -> 0 | F30: =[1]IFE!F97 -> 0 | G30: =[1]IFE!B324 -> 0 | I30: =[1]IFE!C324 -> 0 | J30: =[1]IFE!D324 -> 0
A31: HTHP Fluid Loss | B31: =[1]IFE!D57 -> cc/30min | C31: =CONCATENATE(TEXT([1]IFE!C98,"#.0")&"@"&TEXT([1]IFE!C99,"#")) -> .0@ | D31: =CONCATENATE(TEXT([1]IFE!D98,"#.0")&"@"&TEXT([1]IFE!D99,"#")) -> .0@ | E31: =CONCATENATE(TEXT([1]IFE!E98,"#.0")&"@"&TEXT([1]IFE!E99,"#")) -> .0@ | F31: =CONCATENATE(TEXT([1]IFE!F98,"#.0")&"@"&TEXT([1]IFE!F99,"#")) -> .0@ | G31: =[1]IFE!B325 -> 0 | I31: =[1]IFE!C325 -> 0 | J31: =[1]IFE!D325 -> 0
A32: Cake APT/HT | B32: =[1]IFE!B34 -> 1/32 plg | C32: =CONCATENATE(TEXT([1]IFE!C100,"#")&"/"&TEXT([1]IFE!C101,"#")) -> / | D32: =CONCATENATE(TEXT([1]IFE!D100,"#")&"/"&TEXT([1]IFE!D101,"#")) -> / | E32: =CONCATENATE(TEXT([1]IFE!E100,"#")&"/"&TEXT([1]IFE!E101,"#")) -> / | F32: =CONCATENATE(TEXT([1]IFE!F100,"#")&"/"&TEXT([1]IFE!F101,"#")) -> / | G32: =[1]IFE!B326 -> 0 | I32: =[1]IFE!C326 -> 0 | J32: =[1]IFE!D326 -> 0
A33: Unc Ret Solids | B33: =[1]IFE!D59 -> %Vol | C33: =[1]IFE!C102 -> 4.2 | D33: =[1]IFE!D102 -> 4.2 | E33: =[1]IFE!E102 -> 22 | F33: =[1]IFE!F102 -> 22 | G33: =[1]IFE!B327 -> 0 | I33: =[1]IFE!C327 -> 0 | J33: =[1]IFE!D327 -> 0
A34: Correct Solids | B34: =[1]IFE!D59 -> %Vol | C34: =[1]IFE!C103 -> 0 | D34: =[1]IFE!D103 -> 0 | E34: =[1]IFE!E103 -> 0 | F34: =[1]IFE!F103 -> 0 | G34: SOLIDS CONTROL EQUIPMENT Last 24 hr
A35: Oil | B35: =[1]IFE!D59 -> %Vol | C35: =[1]IFE!C104 -> 95.8 | D35: =[1]IFE!D104 -> 95.8 | E35: =[1]IFE!E104 -> 78 | F35: =[1]IFE!F104 -> 78 | G35: Type | I35: Model/Size | J35: Hrs Used
A36: Uncorr Water | B36: =[1]IFE!D59 -> %Vol | C36: =[1]IFE!C105 -> 0 | D36: =[1]IFE!D105 -> 0 | E36: =[1]IFE!E105 -> 0 | F36: =[1]IFE!F105 -> 0 | G36: =[1]IFE!$B220 -> DERRICK SHEKER 1 | I36: =[1]IFE!$C220 -> 2X100 - 2X140 | J36: =[1]IFE!$D220 -> 0
A37: Oil/Water Ratio | C37: =CONCATENATE(TEXT([1]IFE!C106,"#")&"/"&TEXT([1]IFE!C107,"#")) -> 20/10 | D37: =CONCATENATE(TEXT([1]IFE!D106,"#")&"/"&TEXT([1]IFE!D107,"#")) -> 20/10 | E37: =CONCATENATE(TEXT([1]IFE!E106,"#")&"/"&TEXT([1]IFE!E107,"#")) -> 15/11 | F37: =CONCATENATE(TEXT([1]IFE!F106,"#")&"/"&TEXT([1]IFE!F107,"#")) -> 15/11 | G37: =[1]IFE!$B221 -> DERRICK SHAKER 2 | I37: =[1]IFE!$C221 -> 2X100 - 2X140 | J37: =[1]IFE!$D221 -> 0
A38: Alkal Mud (Pom) | C38: =[1]IFE!C108 -> 85 | D38: =[1]IFE!D108 -> 85 | E38: =[1]IFE!E108 -> 85 | F38: =[1]IFE!F108 -> 85 | G38: =[1]IFE!$B222 -> DERRICK SHAKER 3 | I38: =[1]IFE!$C222 -> 2X100 - 2X140 | J38: =[1]IFE!$D222 -> 0
A39: Cl- Whole Mud | B39: =[1]IFE!D58 -> mg/L | C39: =[1]IFE!C109 -> 0.8 | D39: =[1]IFE!D109 -> 0.8 | E39: =[1]IFE!E109 -> 0 | F39: =[1]IFE!F109 -> 0 | G39: =[1]IFE!$B223 -> MOD 312 / 10T2 w/o pump | I39: =[1]IFE!$C223 -> 4 X 200 | J39: =[1]IFE!$D223 -> 0
A40: Salt | B40: =[1]IFE!D60 -> %Wt | C40: =[1]IFE!C110 -> 0.2 | D40: =[1]IFE!D110 -> 0.2 | E40: =[1]IFE!E110 -> 0 | F40: =[1]IFE!F110 -> 0 | G40: =[1]IFE!$B224 -> 0 | I40: =[1]IFE!$C224 -> 0 | J40: =[1]IFE!$D224 -> 0
A41: Lime | B41: =[1]IFE!B44 -> lb/bbl | C41: =[1]IFE!C111 -> 0.6 | D41: =[1]IFE!D111 -> 0.6 | E41: =[1]IFE!E111 -> 0 | F41: =[1]IFE!F111 -> 0 | G41: =[1]IFE!$B225 -> 0 | I41: =[1]IFE!$C225 -> 0 | J41: =[1]IFE!$D225 -> 0
...

Sheet Extra WBM Labels
J2: ="EXTRA WBM PROPERTIES REPORT No. "&[1]IFE!B166&" " -> EXTRA WBM PROPERTIES REPORT No. 9
A3: Operator : | B3: =[1]IFE!B6 -> Cardon IV | D3: Field/Area : | E3: =[1]IFE!B9 -> Golfo de Venezuela | H3: Depth/TVD : | I3: =[1]IFE!B120&" "&[1]IFE!B30&" /" -> 563 pies / | J3: =[1]IFE!B121&" "&[1]IFE!B30 -> 563 pies
A4: Report For : | B4: =[1]IFE!B125 -> Gerrit Ham / Jhony Quintero | D4: Description : | E4: =[1]IFE!B10 -> Exploratory | H4: Date : | I4: =[1]IFE!B119 -> 39989
A5: Well Name : | B5: =[1]IFE!B8 -> Perla-1X | D5: Location : | E5: =[1]IFE!B11 -> Offshore | H5: Spud Date : | I5: =[1]IFE!B5 -> 39981
A6: Contractor: | B6: =[1]IFE!B15 -> Ensco | D6: Water Depth : | E6: =[1]IFE!B16&" "&[1]IFE!B30 -> 202 pies | H6: Mud Type : | I6: =[1]IFE!B124 -> Agua de mar / HI VIS
A7: Report For : | B7: =[1]IFE!B126 -> Ricky Otwell | D7: Rig Name : | E7: =[1]IFE!Z981 -> 68 | H7: Activity : | I7: =[1]IFE!B123 -> Bajando Tuberia
A8: EXTRA PROPERTIES
A9: Sample From | C9: =CONCATENATE(TEXT([1]IFE!C77," ")&" "&TEXT([1]IFE!C78,"H:MM")) -> TK 1 12:00 | D9: =CONCATENATE(TEXT([1]IFE!D77," ")&" "&TEXT([1]IFE!D78,"H:MM")) -> 0:00 | E9: =CONCATENATE(TEXT([1]IFE!E77," ")&" "&TEXT([1]IFE!E78,"H:MM")) -> TK 3 12:00 | F9: =CONCATENATE(TEXT([1]IFE!F77," ")&" "&TEXT([1]IFE!F78,"H:MM")) -> TK 3 0:00
A10: =[1]IFE!H2801 -> 0 | B10: =[1]IFE!I2801 -> 0 | C10: =[1]IFE!B2801 -> 0 | D10: =[1]IFE!C2801 -> 0 | E10: =[1]IFE!D2801 -> 0 | F10: =[1]IFE!E2801 -> 0
A11: =[1]IFE!H2802 -> 0 | B11: =[1]IFE!I2802 -> 0 | C11: =[1]IFE!B2802 -> 0 | D11: =[1]IFE!C2802 -> 0 | E11: =[1]IFE!D2802 -> 0 | F11: =[1]IFE!E2802 -> 0
A12: =[1]IFE!H2803 -> 0 | B12: =[1]IFE!I2803 -> 0 | C12: =[1]IFE!B2803 -> 0 | D12: =[1]IFE!C2803 -> 0 | E12: =[1]IFE!D2803 -> 0 | F12: =[1]IFE!E2803 -> 0
A13: =[1]IFE!H2804 -> 0 | B13: =[1]IFE!I2804 -> 0 | C13: =[1]IFE!B2804 -> 0 | D13: =[1]IFE!C2804 -> 0 | E13: =[1]IFE!D2804 -> 0 | F13: =[1]IFE!E2804 -> 0
A14: =[1]IFE!H2805 -> 0 | B14: =[1]IFE!I2805 -> 0 | C14: =[1]IFE!B2805 -> 0 | D14: =[1]IFE!C2805 -> 0 | E14: =[1]IFE!D2805 -> 0 | F14: =[1]IFE!E2805 -> 0
A15: =[1]IFE!H2806 -> 0 | B15: =[1]IFE!I2806 -> 0 | C15: =[1]IFE!B2806 -> 0 | D15: =[1]IFE!C2806 -> 0 | E15: =[1]IFE!D2806 -> 0 | F15: =[1]IFE!E2806 -> 0
A16: =[1]IFE!H2807 -> 0 | B16: =[1]IFE!I2807 -> 0 | C16: =[1]IFE!B2807 -> 0 | D16: =[1]IFE!C2807 -> 0 | E16: =[1]IFE!D2807 -> 0 | F16: =[1]IFE!E2807 -> 0
A17: =[1]IFE!H2808 -> 0 | B17: =[1]IFE!I2808 -> 0 | C17: =[1]IFE!B2808 -> 0 | D17: =[1]IFE!C2808 -> 0 | E17: =[1]IFE!D2808 -> 0 | F17: =[1]IFE!E2808 -> 0
A18: =[1]IFE!H2809 -> 0 | B18: =[1]IFE!I2809 -> 0 | C18: =[1]IFE!B2809 -> 0 | D18: =[1]IFE!C2809 -> 0 | E18: =[1]IFE!D2809 -> 0 | F18: =[1]IFE!E2809 -> 0
A19: =[1]IFE!H2810 -> 0 | B19: =[1]IFE!I2810 -> 0 | C19: =[1]IFE!B2810 -> 0 | D19: =[1]IFE!C2810 -> 0 | E19: =[1]IFE!D2810 -> 0 | F19: =[1]IFE!E2810 -> 0
A20: =[1]IFE!H2811 -> 0 | B20: =[1]IFE!I2811 -> 0 | C20: =[1]IFE!B2811 -> 0 | D20: =[1]IFE!C2811 -> 0 | E20: =[1]IFE!D2811 -> 0 | F20: =[1]IFE!E2811 -> 0
A21: =[1]IFE!H2812 -> 0 | B21: =[1]IFE!I2812 -> 0 | C21: =[1]IFE!B2812 -> 0 | D21: =[1]IFE!C2812 -> 0 | E21: =[1]IFE!D2812 -> 0 | F21: =[1]IFE!E2812 -> 0
... A61: =[1]IFE!H2852 -> 0 | B61: =[1]IFE!I2852 -> 0 | C61: =[1]IFE!B2852 -> 0 | D61: =[1]IFE!C2852 -> 0 | E61: =[1]IFE!D2852 -> 0 | F61: =[1]IFE!E2852 -> 0
A62: M-I ENGR / PHONE | C62: RIG PHONE | E62: WAREHOUSE PHONE | G62: DAILY COST | I62: CUMULATIVE COST
A63: =[1]IFE!$B$127&" "&[1]IFE!$B$129 -> Jesus Villarroel 0
A64: =[1]IFE!$B$128 -> Nelson Marcano | C64: =[1]IFE!$D$131 -> 0 | E64: =[1]IFE!B133 -> 0 | G64: =[1]IFE!B134 -> 5749.32 | I64: =[1]IFE!B135 -> 89939.53

Sheet Extra OBM-SBM Labels
J2: ="EXTRA OBM-SBM PROPERTIES REPORT No. "&[1]IFE!B166&" " -> EXTRA OBM-SBM PROPERTIES REPORT No. 9
A3: Operator : | B3: =[1]IFE!B6 -> Cardon IV | D3: Field/Area : | E3: =[1]IFE!B9 -> Golfo de Venezuela | H3: Depth/TVD : | I3: =[1]IFE!B120&" "&[1]IFE!B30&" /" -> 563 pies / | J3: =[1]IFE!B121&" "&[1]IFE!B30 -> 563 pies
A4: Report For : | B4: =[1]IFE!B125 -> Gerrit Ham / Jhony Quintero | D4: Description : | E4: =[1]IFE!B10 -> Exploratory | H4: Date : | I4: =[1]IFE!B119 -> 39989
A5: Well Name : | B5: =[1]IFE!B8 -> Perla-1X | D5: Location : | E5: =[1]IFE!B11 -> Offshore | H5: Spud Date : | I5: =[1]IFE!B5 -> 39981
A6: Contractor: | B6: =[1]IFE!B15 -> Ensco | D6: Water Depth : | E6: =[1]IFE!B16&" "&[1]IFE!B30 -> 202 pies | H6: Mud Type : | I6: =[1]IFE!B124 -> Agua de mar / HI VIS
A7: Report For : | B7: =[1]IFE!B126 -> Ricky Otwell | D7: Rig Name : | E7: =[1]IFE!Z981 -> 68 | H7: Activity : | I7: =[1]IFE!B123 -> Bajando Tuberia
A8: EXTRA PROPERTIES
A9: Sample From | C9: =CONCATENATE(TEXT([1]IFE!C77," ")&" "&TEXT([1]IFE!C78,"H:MM")) -> TK 1 12:00 | D9: =CONCATENATE(TEXT([1]IFE!D77," ")&" "&TEXT([1]IFE!D78,"H:MM")) -> 0:00 | E9: =CONCATENATE(TEXT([1]IFE!E77," ")&" "&TEXT([1]IFE!E78,"H:MM")) -> TK 3 12:00 | F9: =CONCATENATE(TEXT([1]IFE!F77," ")&" "&TEXT([1]IFE!F78,"H:MM")) -> TK 3 0:00
A10: =[1]IFE!J2801 -> 0 | B10: =[1]IFE!K2801 -> 0 | C10: =[1]IFE!B2801 -> 0 | D10: =[1]IFE!C2801 -> 0 | E10: =[1]IFE!D2801 -> 0 | F10: =[1]IFE!E2801 -> 0
A11: =[1]IFE!J2802 -> 0 | B11: =[1]IFE!K2802 -> 0 | C11: =[1]IFE!B2802 -> 0 | D11: =[1]IFE!C2802 -> 0 | E11: =[1]IFE!D2802 -> 0 | F11: =[1]IFE!E2802 -> 0
A12: =[1]IFE!J2803 -> 0 | B12: =[1]IFE!K2803 -> 0 | C12: =[1]IFE!B2803 -> 0 | D12: =[1]IFE!C2803 -> 0 | E12: =[1]IFE!D2803 -> 0 | F12: =[1]IFE!E2803 -> 0
A13: =[1]IFE!J2804 -> 0 | B13: =[1]IFE!K2804 -> 0 | C13: =[1]IFE!B2804 -> 0 | D13: =[1]IFE!C2804 -> 0 | E13: =[1]IFE!D2804 -> 0 | F13: =[1]IFE!E2804 -> 0
A14: =[1]IFE!J2805 -> 0 | B14: =[1]IFE!K2805 -> 0 | C14: =[1]IFE!B2805 -> 0 | D14: =[1]IFE!C2805 -> 0 | E14: =[1]IFE!D2805 -> 0 | F14: =[1]IFE!E2805 -> 0
A15: =[1]IFE!J2806 -> 0 | B15: =[1]IFE!K2806 -> 0 | C15: =[1]IFE!B2806 -> 0 | D15: =[1]IFE!C2806 -> 0 | E15: =[1]IFE!D2806 -> 0 | F15: =[1]IFE!E2806 -> 0
A16: =[1]IFE!J2807 -> 0 | B16: =[1]IFE!K2807 -> 0 | C16: =[1]IFE!B2807 -> 0 | D16: =[1]IFE!C2807 -> 0 | E16: =[1]IFE!D2807 -> 0 | F16: =[1]IFE!E2807 -> 0
A17: =[1]IFE!J2808 -> 0 | B17: =[1]IFE!K2808 -> 0 | C17: =[1]IFE!B2808 -> 0 | D17: =[1]IFE!C2808 -> 0 | E17: =[1]IFE!D2808 -> 0 | F17: =[1]IFE!E2808 -> 0
A18: =[1]IFE!J2809 -> 0 | B18: =[1]IFE!K2809 -> 0 | C18: =[1]IFE!B2809 -> 0 | D18: =[1]IFE!C2809 -> 0 | E18: =[1]IFE!D2809 -> 0 | F18: =[1]IFE!E2809 -> 0
A19: =[1]IFE!J2810 -> 0 | B19: =[1]IFE!K2810 -> 0 | C19: =[1]IFE!B2810 -> 0 | D19: =[1]IFE!C2810 -> 0 | E19: =[1]IFE!D2810 -> 0 | F19: =[1]IFE!E2810 -> 0
A20: =[1]IFE!J2811 -> 0 | B20: =[1]IFE!K2811 -> 0 | C20: =[1]IFE!B2811 -> 0 | D20: =[1]IFE!C2811 -> 0 | E20: =[1]IFE!D2811 -> 0 | F20: =[1]IFE!E2811 -> 0
A21: =[1]IFE!J2812 -> 0 | B21: =[1]IFE!K2812 -> 0 | C21: =[1]IFE!B2812 -> 0 | D21: =[1]IFE!C2812 -> 0 | E21: =[1]IFE!D2812 -> 0 | F21: =[1]IFE!E2812 -> 0
... A61: =[1]IFE!J2852 -> 0 | B61: =[1]IFE!K2852 -> 0 | C61: =[1]IFE!B2852 -> 0 | D61: =[1]IFE!C2852 -> 0 | E61: =[1]IFE!D2852 -> 0 | F61: =[1]IFE!E2852 -> 0
A62: M-I ENGR / PHONE | C62: RIG PHONE | E62: WAREHOUSE PHONE | G62: DAILY COST | I62: CUMULATIVE COST
A63: =[1]IFE!$B$127&" "&[1]IFE!$B$129 -> Jesus Villarroel 0
A64: =[1]IFE!$B$128 -> Nelson Marcano | C64: =[1]IFE!$D$131 -> 0 | E64: =[1]IFE!B133 -> 0 | G64: =[1]IFE!B134 -> 5749.32 | I64: =[1]IFE!B135 -> 89939.53

Sheet Vol. Info
F1: MUD VOLUME ACCOUNTING
F2: Daily Report
A5: Operator : | B5: =[1]IFE!B6 -> Cardon IV | E5: Date : | F5: =SUM([1]IFE!$B$119) -> 39989
A6: Well Name: | B6: =[1]IFE!B8 -> Perla-1X | E6: Report No.: | F6: =SUM([1]IFE!$B$166) -> 9
A8: TANK | B8: CAPACITY | C8: WEIGHT | D8: VOLUME | E8: REMARKS | F8: CLASS | G8: SUM PIT VOLUMES
B9: =[1]IFE!$B$32 -> bbl | C9: =[1]IFE!$B$39 -> lb/gal | D9: =[1]IFE!$B$32 -> bbl
A10: =[1]IFE!$BN$3 -> Pit # 3 | B10: =[1]IFE!$BN$423 -> 586 | C10: =[1]IFE!$BN$63 -> 0 | D10: =[1]IFE!$BN$93 -> 420 | E10: =[1]IFE!BN343 -> 0 | F10: =[1]IFE!$BN$33 -> Reserve | G10: MUD VOLUME | H10: =[1]IFE!$B$32 -> bbl
A11: =[1]IFE!$BN$4 -> Trip tank # 1 | B11: =[1]IFE!$BN$424 -> 40 | C11: =[1]IFE!$BN$64 -> 0 | D11: =[1]IFE!$BN$94 -> 0 | E11: =[1]IFE!BN344 -> 0 | F11: =[1]IFE!$BN$34 -> Reserve | G11: Active | H11: =[1]IFE!$BH$209 -> 0
A12: =[1]IFE!$BN$5 -> Trip tank # 2 | B12: =[1]IFE!$BN$425 -> 40 | C12: =[1]IFE!$BN$65 -> 0 | D12: =[1]IFE!$BN$95 -> 0 | E12: =[1]IFE!BN345 -> 0 | F12: =[1]IFE!$BN$35 -> Reserve | G12: Reserve | H12: =[1]IFE!$BH$210 -> 1418
A13: =[1]IFE!$BN$6 -> Pit # 1 | B13: =[1]IFE!$BN$426 -> 512 | C13: =[1]IFE!$BN$66 -> 0 | D13: =[1]IFE!$BN$96 -> 501 | E13: =[1]IFE!BN346 -> 0 | F13: =[1]IFE!$BN$36 -> Reserve | G13: Premix | H13: =[1]IFE!$BH$211 -> 0
A14: =[1]IFE!$BN$7 -> Pit # 2 | B14: =[1]IFE!$BN$427 -> 586 | C14: =[1]IFE!$BN$67 -> 0 | D14: =[1]IFE!$BN$97 -> 497 | E14: =[1]IFE!BN347 -> 0 | F14: =[1]IFE!$BN$37 -> Reserve | G14: OTHER VOLUME
A15: =[1]IFE!$BN$8 -> Slug Pit | B15: =[1]IFE!$BN$428 -> 75 | C15: =[1]IFE!$BN$68 -> 0 | D15: =[1]IFE!$BN$98 -> 0 | E15: =[1]IFE!BN348 -> 0 | F15: =[1]IFE!$BN$38 -> Reserve | G15: =[1]IFE!$BG$213 -> Base Oil | H15: =[1]IFE!$BH$213 -> 0
A16: =[1]IFE!$BN$9 -> Sand Traps | B16: =[1]IFE!$BN$429 -> 170 | C16: =[1]IFE!$BN$69 -> 0 | D16: =[1]IFE!$BN$99 -> 0 | E16: =[1]IFE!BN349 -> 0 | F16: =[1]IFE!$BN$39 -> Reserve | G16: =[1]IFE!$BG$214 -> Brine | H16: =[1]IFE!$BH$214 -> 0
A17: =[1]IFE!$BN$10 -> 0 | B17: =[1]IFE!$BN$430 -> 0 | C17: =[1]IFE!$BN$70 -> 0 | D17: =[1]IFE!$BN$100 -> 0 | E17: =[1]IFE!BN350 -> 0 | F17: =[1]IFE!$BN$40 -> 0 | G17: =[1]IFE!$BG$215 -> Hole | H17: =[1]IFE!$BH$215 -> 0
A18: =[1]IFE!$BN$11 -> 0 | B18: =[1]IFE!$BN$431 -> 0 | C18: =[1]IFE!$BN$71 -> 0 | D18: =[1]IFE!$BN$101 -> 0 | E18: =[1]IFE!BN351 -> 0 | F18: =[1]IFE!$BN$41 -> 0 | G18: =[1]IFE!$BG$216 -> 0 | H18: =[1]IFE!$BH$216 -> 0
A19: =[1]IFE!$BN$12 -> 0 | B19: =[1]IFE!$BN$432 -> 0 | C19: =[1]IFE!$BN$72 -> 0 | D19: =[1]IFE!$BN$102 -> 0 | E19: =[1]IFE!BN352 -> 0 | F19: =[1]IFE!$BN$42 -> 0 | G19: =[1]IFE!$BG$217 -> 0 | H19: =[1]IFE!$BH$217 -> 0
A20: =[1]IFE!$BN$13 -> 0 | B20: =[1]IFE!$BN$433 -> 0 | C20: =[1]IFE!$BN$73 -> 0 | D20: =[1]IFE!$BN$103 -> 0 | E20: =[1]IFE!BN353 -> 0 | F20: =[1]IFE!$BN$43 -> 0 | G20: =[1]IFE!$BG$218 -> 0 | H20: =[1]IFE!$BH$218 -> 0
A21: =[1]IFE!$BN$14 -> 0 | B21: =[1]IFE!$BN$434 -> 0 | C21: =[1]IFE!$BN$74 -> 0 | D21: =[1]IFE!$BN$104 -> 0 | E21: =[1]IFE!BN354 -> 0 | F21: =[1]IFE!$BN$44 -> 0 | G21: =[1]IFE!$BG$219 -> 0 | H21: =[1]IFE!$BH$219 -> 0
A22: =[1]IFE!$BN$15 -> 0 | B22: =[1]IFE!$BN$435 -> 0 | C22: =[1]IFE!$BN$75 -> 0 | D22: =[1]IFE!$BN$105 -> 0 | E22: =[1]IFE!BN355 -> 0 | F22: =[1]IFE!$BN$45 -> 0 | G22: =[1]IFE!$BG$220 -> 0 | H22: =[1]IFE!$BH$220 -> 0
A23: =[1]IFE!$BN$16 -> 0 | B23: =[1]IFE!$BN$436 -> 0 | C23: =[1]IFE!$BN$76 -> 0 | D23: =[1]IFE!$BN$106 -> 0 | E23: =[1]IFE!BN356 -> 0 | F23: =[1]IFE!$BN$46 -> 0 | G23: =[1]IFE!$BG$221 -> 0 | H23: =[1]IFE!$BH$221 -> 0
A24: =[1]IFE!$BN$17 -> 0 | B24: =[1]IFE!$BN$437 -> 0 | C24: =[1]IFE!$BN$77 -> 0 | D24: =[1]IFE!$BN$107 -> 0 | E24: =[1]IFE!BN357 -> 0 | F24: =[1]IFE!$BN$47 -> 0 | G24: =[1]IFE!$BG$222 -> 0 | H24: =[1]IFE!$BH$222 -> 0
A25: =[1]IFE!$BN$18 -> 0 | B25: =[1]IFE!$BN$438 -> 0 | C25: =[1]IFE!$BN$78 -> 0 | D25: =[1]IFE!$BN$108 -> 0 | E25: =[1]IFE!BN358 -> 0 | F25: =[1]IFE!$BN$48 -> 0 | G25: =[1]IFE!$BG$223 -> 0 | H25: =[1]IFE!$BH$223 -> 0
A26: =[1]IFE!$BN$19 -> 0 | B26: =[1]IFE!$BN$439 -> 0 | C26: =[1]IFE!$BN$79 -> 0 | D26: =[1]IFE!$BN$109 -> 0 | E26: =[1]IFE!BN359 -> 0 | F26: =[1]IFE!$BN$49 -> 0 | G26: =[1]IFE!$BG$224 -> 0 | H26: =[1]IFE!$BH$224 -> 0
A27: =[1]IFE!$BN$20 -> 0 | B27: =[1]IFE!$BN$440 -> 0 | C27: =[1]IFE!$BN$80 -> 0 | D27: =[1]IFE!$BN$110 -> 0 | E27: =[1]IFE!BN360 -> 0 | F27: =[1]IFE!$BN$50 -> 0 | G27: =[1]IFE!$BG$225 -> 0 | H27: =[1]IFE!$BH$225 -> 0
A28: =[1]IFE!$BN$21 -> 0 | B28: =[1]IFE!$BN$441 -> 0 | C28: =[1]IFE!$BN$81 -> 0 | D28: =[1]IFE!$BN$111 -> 0 | E28: =[1]IFE!BN361 -> 0 | F28: =[1]IFE!$BN$51 -> 0 | G28: =[1]IFE!$BG$226 -> 0 | H28: =[1]IFE!$BH$226 -> 0
A29: =[1]IFE!$BN$22 -> 0 | B29: =[1]IFE!$BN$442 -> 0 | C29: =[1]IFE!$BN$82 -> 0 | D29: =[1]IFE!$BN$112 -> 0 | E29: =[1]IFE!BN362 -> 0 | F29: =[1]IFE!$BN$52 -> 0
A30: =[1]IFE!$BN$23 -> 0 | B30: =[1]IFE!$BN$443 -> 0 | C30: =[1]IFE!$BN$83 -> 0 | D30: =[1]IFE!$BN$113 -> 0 | E30: =[1]IFE!BN363 -> 0 | F30: =[1]IFE!$BN$53 -> 0
A31: =[1]IFE!$BN$24 -> 0 | B31: =[1]IFE!$BN$444 -> 0 | C31: =[1]IFE!$BN$84 -> 0 | D31: =[1]IFE!$BN$114 -> 0 | E31: =[1]IFE!BN364 -> 0 | F31: =[1]IFE!$BN$54 -> 0
A32: =[1]IFE!$BN$25 -> 0 | B32: =[1]IFE!$BN$445 -> 0 | C32: =[1]IFE!$BN$85 -> 0 | D32: =[1]IFE!$BN$115 -> 0 | E32: =[1]IFE!BN365 -> 0 | F32: =[1]IFE!$BN$55 -> 0
A33: =[1]IFE!$BN26 -> 0 | B33: =[1]IFE!$BN446 -> 0 | C33: =[1]IFE!$BN86 -> 0 | D33: =[1]IFE!$BN116 -> 0 | E33: =[1]IFE!BN366 -> 0 | F33: =[1]IFE!$BN56 -> 0
A34: =[1]IFE!$BN27 -> 0 | B34: =[1]IFE!$BN447 -> 0 | C34: =[1]IFE!$BN87 -> 0 | D34: =[1]IFE!$BN117 -> 0 | E34: =[1]IFE!BN367 -> 0 | F34: =[1]IFE!$BN57 -> 0
A35: =[1]IFE!$BN28 -> 0 | B35: =[1]IFE!$BN448 -> 0 | C35: =[1]IFE!$BN88 -> 0 | D35: =[1]IFE!$BN118 -> 0 | E35: =[1]IFE!BN368 -> 0 | F35: =[1]IFE!$BN58 -> 0
A36: =[1]IFE!$BN29 -> 0 | B36: =[1]IFE!$BN449 -> 0 | C36: =[1]IFE!$BN89 -> 0 | D36: =[1]IFE!$BN119 -> 0 | E36: =[1]IFE!BN369 -> 0 | F36: =[1]IFE!$BN59 -> 0
A37: =[1]IFE!$BN30 -> 0 | B37: =[1]IFE!$BN450 -> 0 | C37: =[1]IFE!$BN90 -> 0 | D37: =[1]IFE!$BN120 -> 0 | E37: =[1]IFE!BN370 -> 0 | F37: =[1]IFE!$BN60 -> 0
A38: =[1]IFE!$BN31 -> 0 | B38: =[1]IFE!$BN451 -> 0 | C38: =[1]IFE!$BN91 -> 0 | D38: =[1]IFE!$BN121 -> 0 | E38: =[1]IFE!BN371 -> 0 | F38: =[1]IFE!$BN61 -> 0
A39: =[1]IFE!$BN32 -> 0 | B39: =[1]IFE!$BN452 -> 0 | C39: =[1]IFE!$BN92 -> 0 | D39: =[1]IFE!$BN122 -> 0 | E39: =[1]IFE!BN372 -> 0 | F39: =[1]IFE!$BN62 -> 0
C40: MUD IN HOLE (bbls)
A41: MUD IN HOLE: | B41: ANNULUS | C41: PIPE | E41: BELOW BIT | G41: TOTAL
A43: Total Hole Volume | B43: =[1]IFE!$BE$84 -> 0 | C43: =[1]IFE!$BE$83 -> 0 | E43: =[1]IFE!$BE$85 -> 429 | G43: =B43+C43+E43 -> 429
A44: Volume Not Mud | B44: =[1]IFE!$BE$36 -> 0 | C44: =[1]IFE!$BE$37 -> 0 | E44: =[1]IFE!$BE$38 -> 429 | G44: =B44+C44+E44 -> 429
...

Sheet Chem. Inv (DF)
G1: WELLSITE CHEMICAL INVENTORY
G2: Daily Report
B3: Operator : | C3: =[1]IFE!$B$6 -> Cardon IV | I3: Date : | J3: =[1]IFE!$B$119 -> 39989
B4: Well Name : | C4: =[1]IFE!$B$8 -> Perla-1X | I4: Report No: | J4: =[1]IFE!$B$166 -> 9
B5: Location: | C5: =[1]IFE!$B$11 -> Offshore | I5: Page | J5: 1
E6: Cost Summary
D7: Total Daily Cost: | F7: =[1]IFE!$B$134 -> 5749.32 | J7: Total Daily Tax: | K7: =SUM(F7)-R15 -> 0
D8: Cumulative Cost: | F8: =[1]IFE!$B$135 -> 89939.53
A9: Product | C9: Unit | D9: Unit | E9: Start | F9: Daily | G9: Cum | H9: Daily | I9: Cum | J9: Daily | K9: Cum. | L9: Final | M9: Daily | N9: Daily | O9: Cum.
C10: Size | D10: Price | E10: Amt. | F10: Used | G10: Used | H10: Rec'd | I10: Rec'd | J10: Return | K10: Return | L10: Stock | M10: Cost | N10: Cost | O10: Cost
A11: =[1]IFE!$AO$1 -> M-I BAR BULK | C11: =[1]IFE!$AO$2 -> 100. LB BG | D11: =[1]IFE!$AO$10 -> 20.25 | E11: =[1]IFE!$AO$4 -> 1153 | F11: =[1]IFE!$AO$3 -> 0 | G11: =[1]IFE!$AO$9 -> 2206 | H11: =[1]IFE!$AO$5 -> 0 | I11: =[1]IFE!$AQ2 -> 3359 | J11: =[1]IFE!$AO$6 -> 0 | K11: =[1]IFE!$AQ3 -> 0 | L11: =[1]IFE!$AO$7 -> 1153 | M11: =D11*F11 -> 0 | N11: =[1]IFE!$AO$48*F11 -> 0 | O11: =[1]IFE!$AO$48*G11 -> 40700.7
A12: =[1]IFE!$AO$11 -> SODA ASH | C12: =[1]IFE!$AO$12 -> 50. KG BG | D12: =[1]IFE!$AO$20 -> 55.51 | E12: =[1]IFE!$AO$14 -> 10 | F12: =[1]IFE!$AO$13 -> 0 | G12: =[1]IFE!$AO$19 -> 6 | H12: =[1]IFE!$AO$15 -> 0 | I12: =[1]IFE!$AQ12 -> 16 | J12: =[1]IFE!$AO$16 -> 0 | K12: =[1]IFE!$AQ13 -> 0 | L12: =[1]IFE!$AO$17 -> 10 | M12: =D12*F12 -> 0 | Q12: Before Taxes
A13: =[1]IFE!$AO$21 -> SODIUM BICARBONATE | C13: =[1]IFE!$AO$22 -> 50. LB BG | D13: =[1]IFE!$AO$30 -> 52.87 | E13: =[1]IFE!$AO$24 -> 27 | F13: =[1]IFE!$AO$23 -> 0 | G13: =[1]IFE!$AO$29 -> 0 | H13: =[1]IFE!$AO$25 -> 0 | I13: =[1]IFE!$AQ22 -> 27 | J13: =[1]IFE!$AO$26 -> 0 | K13: =[1]IFE!$AQ23 -> 0 | L13: =[1]IFE!$AO$27 -> 27 | M13: =D13*F13 -> 0 | R13: =SUM(M11:M60,M71:M120,M131:M180) -> 5749.32
A14: =[1]IFE!$AO$31 -> POLYPAC R | C14: =[1]IFE!$AO$32 -> 50. LB BG | D14: =[1]IFE!$AO$40 -> 184.5 | E14: =[1]IFE!$AO$34 -> 52 | F14: =[1]IFE!$AO$33 -> 0 | G14: =[1]IFE!$AO$39 -> 18 | H14: =[1]IFE!$AO$35 -> 0 | I14: =[1]IFE!$AQ32 -> 70 | J14: =[1]IFE!$AO$36 -> 0 | K14: =[1]IFE!$AQ33 -> 0 | L14: =[1]IFE!$AO$37 -> 52 | M14: =D14*F14 -> 0 | Q14: Before Taxes (Include Not Print Products)
A15: =[1]IFE!$AO$41 -> LOWA TECH 70/75 | C15: =[1]IFE!$AO$42 -> 50. LB BG | D15: =[1]IFE!$AO$50 -> 18.45 | E15: =[1]IFE!$AO$44 -> 112 | F15: =[1]IFE!$AO$43 -> 0 | G15: =[1]IFE!$AO$49 -> 0 | H15: =[1]IFE!$AO$45 -> 0 | I15: =[1]IFE!$AQ42 -> 224 | J15: =[1]IFE!$AO$46 -> 0 | K15: =[1]IFE!$AQ43 -> 112 | L15: =[1]IFE!$AO$47 -> 112 | M15: =D15*F15 -> 0 | R15: =SUMPRODUCT([1]IFE!$C$1201:$C$1340,[1]IFE!$N$1201:$N$1340) -> 5749.32
A16: =[1]IFE!$AO$51 -> CELL-U-SEAL FINE | C16: =[1]IFE!$AO$52 -> 30. LB BG | D16: =[1]IFE!$AO$60 -> 69.67 | E16: =[1]IFE!$AO$54 -> 114 | F16: =[1]IFE!$AO$53 -> 0 | G16: =[1]IFE!$AO$59 -> 0 | H16: =[1]IFE!$AO$55 -> 0 | I16: =[1]IFE!$AQ52 -> 114 | J16: =[1]IFE!$AO$56 -> 0 | K16: =[1]IFE!$AQ53 -> 0 | L16: =[1]IFE!$AO$57 -> 114 | M16: =D16*F16 -> 0 | N16: =[1]IFE!$AO$58*F16 -> 0 | O16: =[1]IFE!$AO$58*G16 -> 0
A17: =[1]IFE!$AO$61 -> CAUSTIC POTASH (POTASSIUM HYDROXIDE - KOH) | C17: =[1]IFE!$AO$62 -> 25. KG BG | D17: =[1]IFE!$AO$70 -> 113.32 | E17: =[1]IFE!$AO$64 -> 14 | F17: =[1]IFE!$AO$63 -> 0 | G17: =[1]IFE!$AO$69 -> 0 | H17: =[1]IFE!$AO$65 -> 0 | I17: =[1]IFE!$AQ62 -> 14 | J17: =[1]IFE!$AO$66 -> 0 | K17: =[1]IFE!$AQ63 -> 0 | L17: =[1]IFE!$AO$67 -> 14 | M17: =D17*F17 -> 0 | N17: =[1]IFE!$AO$68*F17 -> 0 | O17: =[1]IFE!$AO$68*G17 -> 0
A18: =[1]IFE!$AO$71 -> ENGINEERING SERVICE | C18: =[1]IFE!$AO$72 -> 1. EA | D18: =[1]IFE!$AO$80 -> 1485 | E18: =[1]IFE!$AO$74 -> 0 | F18: =[1]IFE!$AO$73 -> 2 | G18: =[1]IFE!$AO$79 -> 13 | H18: =[1]IFE!$AO$75 -> 0 | I18: =[1]IFE!$AQ72 -> 0 | J18: =[1]IFE!$AO$76 -> 0 | K18: =[1]IFE!$AQ73 -> 0 | L18: =[1]IFE!$AO$77 -> 2 | M18: =D18*F18 -> 2970 | N18: =[1]IFE!$AO$78*F18 -> 2970 | O18: =[1]IFE!$AO$78*G18 -> 19305
A19: =[1]IFE!$AO$81 -> BENTONITE WYOMING | C19: =[1]IFE!$AO$82 -> 100. LB BG | D19: =[1]IFE!$AO$90 -> 28.72 | E19: =[1]IFE!$AO$84 -> 58 | F19: =[1]IFE!$AO$83 -> 1 | G19: =[1]IFE!$AO$89 -> 443 | H19: =[1]IFE!$AO$85 -> 0 | I19: =[1]IFE!$AQ82 -> 500 | J19: =[1]IFE!$AO$86 -> 0 | K19: =[1]IFE!$AQ83 -> 0 | L19: =[1]IFE!$AO$87 -> 57 | M19: =D19*F19 -> 28.72 | N19: =[1]IFE!$AO$88*F19 -> 28.72 | O19: =[1]IFE!$AO$88*G19 -> 12722.96
A20: =[1]IFE!$AO$91 -> DUO-VIS | C20: =[1]IFE!$AO$92 -> 50. LB BG | D20: =[1]IFE!$AO$100 -> 550.12 | E20: =[1]IFE!$AO$94 -> 0 | F20: =[1]IFE!$AO$93 -> 0 | G20: =[1]IFE!$AO$99 -> 0 | H20: =[1]IFE!$AO$95 -> 0 | I20: =[1]IFE!$AQ92 -> 0 | J20: =[1]IFE!$AO$96 -> 0 | K20: =[1]IFE!$AQ93 -> 0 | L20: =[1]IFE!$AO$97 -> 0 | M20: =D20*F20 -> 0 | N20: =[1]IFE!$AO$98*F20 -> 0 | O20: =[1]IFE!$AO$98*G20 -> 0
A21: =[1]IFE!$AO$101 -> PIPE-LAX | C21: =[1]IFE!$AO$102 -> 55. GA DM | D21: =[1]IFE!$AO$110 -> 2385.02 | E21: =[1]IFE!$AO$104 -> 20 | F21: =[1]IFE!$AO$103 -> 0 | G21: =[1]IFE!$AO$109 -> 0 | H21: =[1]IFE!$AO$105 -> 0 | I21: =[1]IFE!$AQ102 -> 20 | J21: =[1]IFE!$AO$106 -> 0 | K21: =[1]IFE!$AQ103 -> 0 | L21: =[1]IFE!$AO$107 -> 20 | M21: =D21*F21 -> 0 | N21: =[1]IFE!$AO$108*F21 -> 0 | O21: =[1]IFE!$AO$108*G21 -> 0
A22: =[1]IFE!$AO$111 -> LIME | C22: =[1]IFE!$AO$112 -> 20. KG BG | D22: =[1]IFE!$AO$120 -> 37.43 | E22: =[1]IFE!$AO$114 -> 39 | F22: =[1]IFE!$AO$113 -> 0 | G22: =[1]IFE!$AO$119 -> 0 | H22: =[1]IFE!$AO$115 -> 0 | I22: =[1]IFE!$AQ112 -> 39 | J22: =[1]IFE!$AO$116 -> 0 | K22: =[1]IFE!$AQ113 -> 0 | L22: =[1]IFE!$AO$117 -> 39 | M22: =D22*F22 -> 0 | N22: =[1]IFE!$AO$118*F22 -> 0 | O22: =[1]IFE!$AO$118*G22 -> 0
A23: =[1]IFE!$AO$121 -> THINSMART | C23: =[1]IFE!$AO$122 -> 25. LB BG | D23: =[1]IFE!$AO$130 -> 119.83 | E23: =[1]IFE!$AO$124 -> 117 | F23: =[1]IFE!$AO$123 -> 0 | G23: =[1]IFE!$AO$129 -> 43 | H23: =[1]IFE!$AO$125 -> 0 | I23: =[1]IFE!$AQ122 -> 160 | J23: =[1]IFE!$AO$126 -> 0 | K23: =[1]IFE!$AQ123 -> 0 | L23: =[1]IFE!$AO$127 -> 117 | M23: =D23*F23 -> 0 | N23: =[1]IFE!$AO$128*F23 -> 0 | O23: =[1]IFE!$AO$128*G23 -> 5152.69
A24: =[1]IFE!$AO$131 -> CAUSTIC SODA | C24: =[1]IFE!$AO$132 -> 25. KG BG | D24: =[1]IFE!$AO$140 -> 64.72 | E24: =[1]IFE!$AO$134 -> 21 | F24: =[1]IFE!$AO$133 -> 0 | G24: =[1]IFE!$AO$139 -> 9 | H24: =[1]IFE!$AO$135 -> 0 | I24: =[1]IFE!$AQ132 -> 30 | J24: =[1]IFE!$AO$136 -> 0 | K24: =[1]IFE!$AQ133 -> 0 | L24: =[1]IFE!$AO$137 -> 21 | M24: =D24*F24 -> 0 | N24: =[1]IFE!$AO$138*F24 -> 0 | O24: =[1]IFE!$AO$138*G24 -> 582.48
A25: =[1]IFE!$AO$141 -> DRIL-KLEEN | C25: =[1]IFE!$AO$142 -> 5. GA CN | D25: =[1]IFE!$AO$150 -> 322.21 | E25: =[1]IFE!$AO$144 -> 45 | F25: =[1]IFE!$AO$143 -> 0 | G25: =[1]IFE!$AO$149 -> 0 | H25: =[1]IFE!$AO$145 -> 0 | I25: =[1]IFE!$AQ142 -> 45 | J25: =[1]IFE!$AO$146 -> 0 | K25: =[1]IFE!$AQ143 -> 0 | L25: =[1]IFE!$AO$147 -> 45 | M25: =D25*F25 -> 0 | N25: =[1]IFE!$AO$148*F25 -> 0 | O25: =[1]IFE!$AO$148*G24 -> 2899.89
A26: =[1]IFE!$AO$151 -> PECAN NUT PLUG CSE | C26: =[1]IFE!$AO$152 -> 50. LB BG | D26: =[1]IFE!$AO$160 -> 65.29 | E26: =[1]IFE!$AO$154 -> 25 | F26: =[1]IFE!$AO$153 -> 0 | G26: =[1]IFE!$AO$159 -> 0 | H26: =[1]IFE!$AO$155 -> 0 | I26: =[1]IFE!$AQ152 -> 25 | J26: =[1]IFE!$AO$156 -> 0 | K26: =[1]IFE!$AQ153 -> 0 | L26: =[1]IFE!$AO$157 -> 25 | M26: =D26*F26 -> 0 | N26: =[1]IFE!$AO$158*F26 -> 0 | O26: =[1]IFE!$AO$158*G25 -> 0
A27: =[1]IFE!$AO$161 -> G-SEAL PLUS | C27: =[1]IFE!$AO$162 -> 25. KG BG | D27: =[1]IFE!$AO$170 -> 178.41 | E27: =[1]IFE!$AO$164 -> 35 | F27: =[1]IFE!$AO$163 -> 0 | G27: =[1]IFE!$AO$169 -> 0 | H27: =[1]IFE!$AO$165 -> 0 | I27: =[1]IFE!$AQ162 -> 35 | J27: =[1]IFE!$AO$166 -> 0 | K27: =[1]IFE!$AQ163 -> 0 | L27: =[1]IFE!$AO$167 -> 35 | M27: =D27*F27 -> 0 | N27: =[1]IFE!$AO$168*F27 -> 0 | O27: =[1]IFE!$AO$168*G26 -> 0
A28: =[1]IFE!$AO$171 -> CALCIUM CARBONATE #6 | C28: =[1]IFE!$AO$172 -> 50. LB BG | D28: =[1]IFE!$AO$180 -> 18.45 | E28: =[1]IFE!$AO$174 -> 112 | F28: =[1]IFE!$AO$173 -> 0 | G28: =[1]IFE!$AO$179 -> 0 | H28: =[1]IFE!$AO$175 -> 0 | I28: =[1]IFE!$AQ172 -> 112 | J28: =[1]IFE!$AO$176 -> 0 | K28: =[1]IFE!$AQ173 -> 0 | L28: =[1]IFE!$AO$177 -> 112 | M28: =D28*F28 -> 0 | N28: =[1]IFE!$AO$178*F28 -> 0 | O28: =[1]IFE!$AO$178*G27 -> 0
A29: =[1]IFE!$AO$181 -> DUO-VIS | C29: =[1]IFE!$AO$182 -> 25. KG BG | D29: =[1]IFE!$AO$190 -> 550.12 | E29: =[1]IFE!$AO$184 -> 56 | F29: =[1]IFE!$AO$183 -> 5 | G29: =[1]IFE!$AO$189 -> 7 | H29: =[1]IFE!$AO$185 -> 0 | I29: =[1]IFE!$AQ182 -> 58 | J29: =[1]IFE!$AO$186 -> 0 | K29: =[1]IFE!$AQ183 -> 0 | L29: =[1]IFE!$AO$187 -> 51 | M29: =D29*F29 -> 2750.6 | N29: =[1]IFE!$AO$198*F29 -> 0 | O29: =[1]IFE!$AO$188*G28 -> 0
A30: =[1]IFE!$AO$191 -> 0 | C30: =[1]IFE!$AO$192 -> 0 | D30: =[1]IFE!$AO$200 -> 0 | E30: =[1]IFE!$AO$194 -> 0 | F30: =[1]IFE!$AO$193 -> 0 | G30: =[1]IFE!$AO$199 -> 0 | H30: =[1]IFE!$AO$195 -> 0 | I30: =[1]IFE!$AQ192 -> 0 | J30: =[1]IFE!$AO$196 -> 0 | K30: =[1]IFE!$AQ193 -> 0 | L30: =[1]IFE!$AO$197 -> 0 | M30: =D30*F30 -> 0 | N30: =[1]IFE!$AO$208*F30 -> 0 | O30: =[1]IFE!$AO$198*G29 -> 0
A31: =[1]IFE!$AO$201 -> 0 | C31: =[1]IFE!$AO$202 -> 0 | D31: =[1]IFE!$AO$210 -> 0 | E31: =[1]IFE!$AO$204 -> 0 | F31: =[1]IFE!$AO$203 -> 0 | G31: =[1]IFE!$AO$209 -> 0 | H31: =[1]IFE!$AO$205 -> 0 | I31: =[1]IFE!$AQ202 -> 0 | J31: =[1]IFE!$AO$206 -> 0 | K31: =[1]IFE!$AQ203 -> 0 | L31: =[1]IFE!$AO$207 -> 0 | M31: =D31*F31 -> 0 | N31: =[1]IFE!$AO$218*F31 -> 0 | O31: =[1]IFE!$AO$208*G30 -> 0
A32: =[1]IFE!$AO$211 -> 0 | C32: =[1]IFE!$AO$212 -> 0 | D32: =[1]IFE!$AO$220 -> 0 | E32: =[1]IFE!$AO$214 -> 0 | F32: =[1]IFE!$AO$213 -> 0 | G32: =[1]IFE!$AO$219 -> 0 | H32: =[1]IFE!$AO$215 -> 0 | I32: =[1]IFE!$AQ212 -> 0 | J32: =[1]IFE!$AO$216 -> 0 | K32: =[1]IFE!$AQ213 -> 0 | L32: =[1]IFE!$AO$217 -> 0 | M32: =D32*F32 -> 0 | N32: =[1]IFE!$AO$228*F32 -> 0 | O32: =[1]IFE!$AO$218*G31 -> 0
